Workbook
Name valuevx: Calculator!$A$1
Name strategy: Calculator!$F$52
Name creditor_table: Calculator!$B$7:$E$30
Name snowball: Calculator!$F$53

Sheet Nov 2024
A1: Budget Calendar with Daily Balance
A2: Year: | B2: 2024 | D2: Month: | E2: 11 | G2: Start Day: | H2: 1 | I2: 1=Sun, 2=Mon … | T2: © 2020 Vertex42 LLC
T3: https://www.vertex42.com/calendars/budget-calendar.html
A5: =UPPER(TEXT(B8,"mmmm yyyy")) -> NOVEMBER 2024 | L5: Start Balance | M5: 2147 | R5: Cash In | S5: =SUMIF(A18:N21,">0")+SUMIF(A24:N27,">0")+SUMIF(A30:N33,">0")+SUMIF(A36:N39,">0")+SUMIF(A42:D45,">0")+SUMIF(S12:S45,">0")+SUMIF(A12:N15,">0") -> 7638.25 | V5: =sum(S5+S6) -> 2595.997
L6: End Balance | M6: =D46 -> 4742.997 | R6: Cash Out | S6: =SUMIF(A18:N21,"<0")+SUMIF(A24:N27,"<0")+SUMIF(A30:N33,"<0")+SUMIF(A36:N39,"<0")+SUMIF(A42:D45,"<0")+SUMIF(S12:S199,"<0")+SUMIF(A12:N15,"<0") -> -5042.253
A8: Date: | B8: =DATE(B2,E2,1) -> 45597
A9: =A17 -> 45599 | C9: =C17 -> 45600 | E9: =E17 -> 45601 | G9: =G17 -> 45602 | I9: =I17 -> 45603 | K9: =K17 -> 45604 | M9: =M17 -> 45605 | P9: MONTHLY BUDGET (EVERYDOLLAR)
A11: =IF(WEEKDAY($B$8,1)=$H$2,$B$8,"") | B11: =SUMIF($T$11:$T$127,A11,$S$11:$S$87) -> 0 | C11: =IF(A11="",IF(WEEKDAY($B$8,1)=MOD($H$2,7)+1,$B$8,""),A11+1) | D11: =SUMIF($T$11:$T$127,C11,$S$11:$S$87) -> 0 | E11: =IF(C11="",IF(WEEKDAY($B$8,1)=MOD($H$2+1,7)+1,$B$8,""),C11+1) | F11: =SUMIF($T$11:$T$127,E11,$S$11:$S$87) -> 0 | G11: =IF(E11="",IF(WEEKDAY($B$8,1)=MOD($H$2+2,7)+1,$B$8,""),E11+1) | H11: =SUMIF($T$11:$T$127,G11,$S$11:$S$87) -> 0 | I11: =IF(G11="",IF(WEEKDAY($B$8,1)=MOD($H$2+3,7)+1,$B$8,""),G11+1) | J11: =SUMIF($T$11:$T$127,I11,$S$11:$S$87) -> 0 | K11: =IF(I11="",IF(WEEKDAY($B$8,1)=MOD($H$2+4,7)+1,$B$8,""),I11+1) -> 45597 | L11: =SUMIF($T$11:$T$127,K11,$S$11:$S$87) -> 337.067 | M11: =IF(K11="",IF(WEEKDAY($B$8,1)=MOD($H$2+5,7)+1,$B$8,""),K11+1) -> 45598 | N11: =SUMIF($T$11:$T$127,M11,$S$11:$S$87) -> 0 | P11: BILL | Q11: ✔ | R11: DAY | S11: AMOUNT | T11: DUE DATE
P12: Check # 1 | R12: 1 | S12: 2004.44 | T12: =IF(ISBLANK(R12),"-",IF(R12>DAY(EOMONTH(DATE($B$2,$E$2,1),0)),EOMONTH(DATE($B$2,$E$2,1),0),DATE($B$2,$E$2,R12))) -> 45597
P13: Check #2 | R13: 1 | S13: 800 | T13: =IF(ISBLANK(R13),"-",IF(R13>DAY(EOMONTH(DATE($B$2,$E$2,1),0)),EOMONTH(DATE($B$2,$E$2,1),0),DATE($B$2,$E$2,R13))) -> 45597
P14: Mortgage | R14: 1 | S14: -1561 | T14: =IF(ISBLANK(R14),"-",IF(R14>DAY(EOMONTH(DATE($B$2,$E$2,1),0)),EOMONTH(DATE($B$2,$E$2,1),0),DATE($B$2,$E$2,R14))) -> 45597
P15: Pay Off Mats | R15: 1 | S15: -185 | T15: =IF(ISBLANK(R15),"-",IF(R15>DAY(EOMONTH(DATE($B$2,$E$2,1),0)),EOMONTH(DATE($B$2,$E$2,1),0),DATE($B$2,$E$2,R15))) -> 45597
A16: BAL: | B16: =$M$5+SUM(B11:B15) -> 2147 | D16: =B16+SUM(D11:D15) -> 2147 | F16: =D16+SUM(F11:F15) -> 2147 | H16: =F16+SUM(H11:H15) -> 2147 | J16: =H16+SUM(J11:J15) -> 2147 | L16: =J16+SUM(L11:L15) -> 2484.067 | N16: =L16+SUM(N11:N15) -> 2484.067 | P16: Pay off Phone | R16: 1 | S16: -566.373 | T16: =IF(ISBLANK(R16),"-",IF(R16>DAY(EOMONTH(DATE($B$2,$E$2,1),0)),EOMONTH(DATE($B$2,$E$2,1),0),DATE($B$2,$E$2,R16))) -> 45597
A17: =IF(M11="","",IF(MONTH(M11+1)<>MONTH(M11),"",M11+1)) -> 45599 | B17: =SUMIF($T$11:$T$127,A17,$S$11:$S$87) -> -33 | C17: =IF(A17="","",IF(MONTH(A17+1)<>MONTH(A17),"",A17+1)) -> 45600 | D17: =SUMIF($T$11:$T$127,C17,$S$11:$S$87) -> -150 | E17: =IF(C17="","",IF(MONTH(C17+1)<>MONTH(C17),"",C17+1)) -> 45601 | F17: =SUMIF($T$11:$T$127,E17,$S$11:$S$87) -> -1088.19 | G17: =IF(E17="","",IF(MONTH(E17+1)<>MONTH(E17),"",E17+1)) -> 45602 | H17: =SUMIF($T$11:$T$127,G17,$S$11:$S$87) -> 0 | I17: =IF(G17="","",IF(MONTH(G17+1)<>MONTH(G17),"",G17+1)) -> 45603 | J17: =SUMIF($T$11:$T$127,I17,$S$11:$S$87) -> 0 | K17: =IF(I17="","",IF(MONTH(I17+1)<>MONTH(I17),"",I17+1)) -> 45604 | L17: =SUMIF($T$11:$T$127,K17,$S$11:$S$87) -> -35 | M17: =IF(K17="","",IF(MONTH(K17+1)<>MONTH(K17),"",K17+1)) -> 45605 | N17: =SUMIF($T$11:$T$127,M17,$S$11:$S$87) -> -451 | P17: YMCA | R17: 1 | S17: -57 | T17: =IF(ISBLANK(R17),"-",IF(R17>DAY(EOMONTH(DATE($B$2,$E$2,1),0)),EOMONTH(DATE($B$2,$E$2,1),0),DATE($B$2,$E$2,R17))) -> 45597 | V17: Emergency Loan | X17: 739
P18: YMCA After School | R18: 1 | S18: -98 | T18: =IF(ISBLANK(R18),"-",IF(R18>DAY(EOMONTH(DATE($B$2,$E$2,1),0)),EOMONTH(DATE($B$2,$E$2,1),0),DATE($B$2,$E$2,R18))) -> 45597
P19: Pest Control | R19: 3 | S19: -33 | T19: =IF(ISBLANK(R19),"-",IF(R19>DAY(EOMONTH(DATE($B$2,$E$2,1),0)),EOMONTH(DATE($B$2,$E$2,1),0),DATE($B$2,$E$2,R19))) -> 45599
P20: Vegas | R20: 4 | S20: -150 | T20: =IF(ISBLANK(R20),"-",IF(R20>DAY(EOMONTH(DATE($B$2,$E$2,1),0)),EOMONTH(DATE($B$2,$E$2,1),0),DATE($B$2,$E$2,R20))) -> 45600
P21: Amazon Prime | R21: 5 | S21: -16.19 | T21: =IF(ISBLANK(R21),"-",IF(R21>DAY(EOMONTH(DATE($B$2,$E$2,1),0)),EOMONTH(DATE($B$2,$E$2,1),0),DATE($B$2,$E$2,R21))) -> 45601
A22: BAL: | B22: =N16+SUM(B17:B21) -> 2451.067 | D22: =B22+SUM(D17:D21) -> 2301.067 | F22: =D22+SUM(F17:F21) -> 1212.877 | H22: =F22+SUM(H17:H21) -> 1212.877 | J22: =H22+SUM(J17:J21) -> 1212.877 | L22: =J22+SUM(L17:L21) -> 1177.877 | N22: =L22+SUM(N17:N21) -> 726.877 | P22: Car Insurance | R22: 5 | S22: -184 | T22: =IF(ISBLANK(R22),"-",IF(R22>DAY(EOMONTH(DATE($B$2,$E$2,1),0)),EOMONTH(DATE($B$2,$E$2,1),0),DATE($B$2,$E$2,R22))) -> 45601 | V22: AA | W22: Account Adjustment
A23: =IF(M17="","",IF(MONTH(M17+1)<>MONTH(M17),"",M17+1)) -> 45606 | B23: =SUMIF($T$11:$T$127,A23,$S$11:$S$87) -> 0 | C23: =IF(A23="","",IF(MONTH(A23+1)<>MONTH(A23),"",A23+1)) -> 45607 | D23: =SUMIF($T$11:$T$127,C23,$S$11:$S$87) -> -228 | E23: =IF(C23="","",IF(MONTH(C23+1)<>MONTH(C23),"",C23+1)) -> 45608 | F23: =SUMIF($T$11:$T$127,E23,$S$11:$S$87) -> -102 | G23: =IF(E23="","",IF(MONTH(E23+1)<>MONTH(E23),"",E23+1)) -> 45609 | H23: =SUMIF($T$11:$T$127,G23,$S$11:$S$87) -> 1906.44 | I23: =IF(G23="","",IF(MONTH(G23+1)<>MONTH(G23),"",G23+1)) -> 45610 | J23: =SUMIF($T$11:$T$127,I23,$S$11:$S$87) -> 0 | K23: =IF(I23="","",IF(MONTH(I23+1)<>MONTH(I23),"",I23+1)) -> 45611 | L23: =SUMIF($T$11:$T$127,K23,$S$11:$S$87) -> 0 | M23: =IF(K23="","",IF(MONTH(K23+1)<>MONTH(K23),"",K23+1)) -> 45612 | N23: =SUMIF($T$11:$T$127,M23,$S$11:$S$87) -> 0 | P23: John Cap One | R23: 5 | S23: -96 | T23: =IF(ISBLANK(R23),"-",IF(R23>DAY(EOMONTH(DATE($B$2,$E$2,1),0)),EOMONTH(DATE($B$2,$E$2,1),0),DATE($B$2,$E$2,R23))) -> 45601
E24: Greenlight | F24: -4.16 | K24: AA | L24: 74.93 | P24: Kia Car Payment | R24: 5 | S24: -792 | T24: =IF(ISBLANK(R24),"-",IF(R24>DAY(EOMONTH(DATE($B$2,$E$2,1),0)),EOMONTH(DATE($B$2,$E$2,1),0),DATE($B$2,$E$2,R24))) -> 45601
P25: Emergency Loan | R25: 8 | S25: -35 | T25: =IF(ISBLANK(R25),"-",IF(R25>DAY(EOMONTH(DATE($B$2,$E$2,1),0)),EOMONTH(DATE($B$2,$E$2,1),0),DATE($B$2,$E$2,R25))) -> 45604
P26: Upgrade Loan | R26: 9 | S26: -451 | T26: =IF(ISBLANK(R26),"-",IF(R26>DAY(EOMONTH(DATE($B$2,$E$2,1),0)),EOMONTH(DATE($B$2,$E$2,1),0),DATE($B$2,$E$2,R26))) -> 45605
P27: Tia Cap One | R27: 11 | S27: -80 | T27: =IF(ISBLANK(R27),"-",IF(R27>DAY(EOMONTH(DATE($B$2,$E$2,1),0)),EOMONTH(DATE($B$2,$E$2,1),0),DATE($B$2,$E$2,R27))) -> 45607
A28: BAL: | B28: =N22+SUM(B23:B27) -> 726.877 | D28: =B28+SUM(D23:D27) -> 498.877 | F28: =D28+SUM(F23:F27) -> 392.717 | H28: =F28+SUM(H23:H27) -> 2299.157 | J28: =H28+SUM(J23:J27) -> 2299.157 | L28: =J28+SUM(L23:L27) -> 2374.087 | N28: =L28+SUM(N23:N27) -> 2374.087 | P28: Tidal Wave | R28: 11 | S28: -50 | T28: =IF(ISBLANK(R28),"-",IF(R28>DAY(EOMONTH(DATE($B$2,$E$2,1),0)),EOMONTH(DATE($B$2,$E$2,1),0),DATE($B$2,$E$2,R28))) -> 45607
A29: =IF(M23="","",IF(MONTH(M23+1)<>MONTH(M23),"",M23+1)) -> 45613 | B29: =SUMIF($T$11:$T$127,A29,$S$11:$S$87) -> -9.99 | C29: =IF(A29="","",IF(MONTH(A29+1)<>MONTH(A29),"",A29+1)) -> 45614 | D29: =SUMIF($T$11:$T$127,C29,$S$11:$S$87) -> -150 | E29: =IF(C29="","",IF(MONTH(C29+1)<>MONTH(C29),"",C29+1)) -> 45615 | F29: =SUMIF($T$11:$T$127,E29,$S$11:$S$87) -> 0 | G29: =IF(E29="","",IF(MONTH(E29+1)<>MONTH(E29),"",E29+1)) -> 45616 | H29: =SUMIF($T$11:$T$127,G29,$S$11:$S$87) -> 0 | I29: =IF(G29="","",IF(MONTH(G29+1)<>MONTH(G29),"",G29+1)) -> 45617 | J29: =SUMIF($T$11:$T$127,I29,$S$11:$S$87) -> 0 | K29: =IF(I29="","",IF(MONTH(I29+1)<>MONTH(I29),"",I29+1)) -> 45618 | L29: =SUMIF($T$11:$T$127,K29,$S$11:$S$87) -> 0 | M29: =IF(K29="","",IF(MONTH(K29+1)<>MONTH(K29),"",K29+1)) -> 45619 | N29: =SUMIF($T$11:$T$127,M29,$S$11:$S$87) -> 0 | P29: YMCA After School | R29: 11 | S29: -98 | T29: =IF(ISBLANK(R29),"-",IF(R29>DAY(EOMONTH(DATE($B$2,$E$2,1),0)),EOMONTH(DATE($B$2,$E$2,1),0),DATE($B$2,$E$2,R29))) -> 45607
G30: Cheer | H30: -42.96 | P30: Google | R30: 12 | S30: -102 | T30: =IF(ISBLANK(R30),"-",IF(R30>DAY(EOMONTH(DATE($B$2,$E$2,1),0)),EOMONTH(DATE($B$2,$E$2,1),0),DATE($B$2,$E$2,R30))) -> 45608
P31: Check # 3 | R31: 13 | S31: 2004.44 | T31: =IF(ISBLANK(R31),"-",IF(R31>DAY(EOMONTH(DATE($B$2,$E$2,1),0)),EOMONTH(DATE($B$2,$E$2,1),0),DATE($B$2,$E$2,R31))) -> 45609 | V31: Vegas | X31: 750
P32: YMCA After School | R32: 13 | S32: -98 | T32: =IF(ISBLANK(R32),"-",IF(R32>DAY(EOMONTH(DATE($B$2,$E$2,1),0)),EOMONTH(DATE($B$2,$E$2,1),0),DATE($B$2,$E$2,R32))) -> 45609 | W32: Plane Ticket | X32: -600
P33: Apple | R33: 17 | S33: -9.99 | T33: =IF(ISBLANK(R33),"-",IF(R33>DAY(EOMONTH(DATE($B$2,$E$2,1),0)),EOMONTH(DATE($B$2,$E$2,1),0),DATE($B$2,$E$2,R33))) -> 45613 | X33: =sum(X31:X32) -> 150
A34: BAL: | B34: =N28+SUM(B29:B33) -> 2364.097 | D34: =B34+SUM(D29:D33) -> 2214.097 | F34: =D34+SUM(F29:F33) -> 2214.097 | H34: =F34+SUM(H29:H33) -> 2171.137 | J34: =H34+SUM(J29:J33) -> 2171.137 | L34: =J34+SUM(L29:L33) -> 2171.137 | N34: =L34+SUM(N29:N33) -> 2171.137 | P34: Vegas | R34: 18 | S34: -150 | T34: =IF(ISBLANK(R34),"-",IF(R34>DAY(EOMONTH(DATE($B$2,$E$2,1),0)),EOMONTH(DATE($B$2,$E$2,1),0),DATE($B$2,$E$2,R34))) -> 45614
A35: =IF(M29="","",IF(MONTH(M29+1)<>MONTH(M29),"",M29+1)) -> 45620 | B35: =SUMIF($T$11:$T$127,A35,$S$11:$S$87) -> 0 | C35: =IF(A35="","",IF(MONTH(A35+1)<>MONTH(A35),"",A35+1)) -> 45621 | D35: =SUMIF($T$11:$T$127,C35,$S$11:$S$87) -> -29.34 | E35: =IF(C35="","",IF(MONTH(C35+1)<>MONTH(C35),"",C35+1)) -> 45622 | F35: =SUMIF($T$11:$T$127,E35,$S$11:$S$87) -> 2754.44 | G35: =IF(E35="","",IF(MONTH(E35+1)<>MONTH(E35),"",E35+1)) -> 45623 | H35: =SUMIF($T$11:$T$127,G35,$S$11:$S$87) -> -98 | I35: =IF(G35="","",IF(MONTH(G35+1)<>MONTH(G35),"",G35+1)) -> 45624 | J35: =SUMIF($T$11:$T$127,I35,$S$11:$S$87) -> -40.55 | K35: =IF(I35="","",IF(MONTH(I35+1)<>MONTH(I35),"",I35+1)) -> 45625 | L35: =SUMIF($T$11:$T$127,K35,$S$11:$S$87) -> 0 | M35: =IF(K35="","",IF(MONTH(K35+1)<>MONTH(K35),"",K35+1)) -> 45626 | N35: =SUMIF($T$11:$T$127,M35,$S$11:$S$87) -> -11 | P35: Dribble Up | R35: 25 | S35: -18.35 | T35: =IF(ISBLANK(R35),"-",IF(R35>DAY(EOMONTH(DATE($B$2,$E$2,1),0)),EOMONTH(DATE($B$2,$E$2,1),0),DATE($B$2,$E$2,R35))) -> 45621
A36: Apl | B36: -3.26 | L36: -0.43 | P36: Disney/Hulu | R36: 25 | S36: -10.99 | T36: =IF(ISBLANK(R36),"-",IF(R36>DAY(EOMONTH(DATE($B$2,$E$2,1),0)),EOMONTH(DATE($B$2,$E$2,1),0),DATE($B$2,$E$2,R36))) -> 45621
P37: Check #1 | R37: 26 | S37: 750 | T37: =IF(ISBLANK(R37),"-",IF(R37>DAY(EOMONTH(DATE($B$2,$E$2,1),0)),EOMONTH(DATE($B$2,$E$2,1),0),DATE($B$2,$E$2,R37))) -> 45622
P38: Check #4 | R38: 26 | S38: 2004.44 | T38: =IF(ISBLANK(R38),"-",IF(R38>DAY(EOMONTH(DATE($B$2,$E$2,1),0)),EOMONTH(DATE($B$2,$E$2,1),0),DATE($B$2,$E$2,R38))) -> 45622
P39: Greenlight | R39: 28 | S39: -6 | T39: =IF(ISBLANK(R39),"-",IF(R39>DAY(EOMONTH(DATE($B$2,$E$2,1),0)),EOMONTH(DATE($B$2,$E$2,1),0),DATE($B$2,$E$2,R39))) -> 45624
A40: BAL: | B40: =N34+SUM(B35:B39) -> 2167.877 | D40: =B40+SUM(D35:D39) -> 2138.537 | F40: =D40+SUM(F35:F39) -> 4892.977 | H40: =F40+SUM(H35:H39) -> 4794.977 | J40: =H40+SUM(J35:J39) -> 4754.427 | L40: =J40+SUM(L35:L39) -> 4753.997 | N40: =L40+SUM(N35:N39) -> 4742.997 | P40: HOC | R40: 28 | S40: -7.55 | T40: =IF(ISBLANK(R40),"-",IF(R40>DAY(EOMONTH(DATE($B$2,$E$2,1),0)),EOMONTH(DATE($B$2,$E$2,1),0),DATE($B$2,$E$2,R40))) -> 45624
A41: =IF(M35="","",IF(MONTH(M35+1)<>MONTH(M35),"",M35+1)) | B41: =SUMIF($T$11:$T$127,A41,$S$11:$S$87) -> 0 | C41: =IF(A41="","",IF(MONTH(A41+1)<>MONTH(A41),"",A41+1)) | D41: =SUMIF($T$11:$T$127,C41,$S$11:$S$87) -> 0 | F41: NOTES | P41: Netflix | R41: 28 | S41: -24 | T41: =IF(ISBLANK(R41),"-",IF(R41>DAY(EOMONTH(DATE($B$2,$E$2,1),0)),EOMONTH(DATE($B$2,$E$2,1),0),DATE($B$2,$E$2,R41))) -> 45624
F42: Remember to make copies of the worksheet before entering daily expenses. | T42: =IF(ISBLANK(R42),"-",IF(R42>DAY(EOMONTH(DATE($B$2,$E$2,1),0)),EOMONTH(DATE($B$2,$E$2,1),0),DATE($B$2,$E$2,R42))) -> -
P43: Peacock | R43: 28 | S43: -3 | T43: =IF(ISBLANK(R43),"-",IF(R43>DAY(EOMONTH(DATE($B$2,$E$2,1),0)),EOMONTH(DATE($B$2,$E$2,1),0),DATE($B$2,$E$2,R43))) -> 45624
...

Sheet Dashboard
A2: BILL | B2: ✔ | C2: DAY | D2: AMOUNT | E2: DUE DATE
A3: Amazon Music | C3: 30 | D3: -18.35
A4: Amazon Prime | C4: 6 | D4: -16.19
A5: Apple | C5: 17 | D5: -9.99
A6: Apple Music | C6: 30 | D6: -11
A7: Cap One | C7: 4 | D7: -96
A8: Car Insurance | C8: 5 | D8: -183.53
A9: Check # 1 | C9: 12 | D9: 2004.44
A10: Check # 3 | C10: 27 | D10: 2004.44
A12: Disney/Hulu | C12: 23 | D12: -12 | G12: 1
A13: Dribble Up | C13: 26 | D13: -18.35
A14: Emergency Loan | C14: 9 | D14: -35
A15: Google | C15: 12 | D15: -102
A16: Greenlight | C16: 10 | D16: -5
A17: Greenlight | C17: 24 | D17: -6
A18: HOC | C18: 26 | D18: -7.55
A19: Kia Car Payment | C19: 5 | D19: -791.16
A20: Mortgage | C20: 3 | D20: -1560.81
A21: Netflix | C21: 9 | D21: -24
A22: Peacock | C22: 30 | D22: -3
A23: Pest Control | C23: 4 | D23: -33
A24: Tia Cap One | C24: 10 | D24: -80
... A38: YMCA After School | C38: 21 | D38: -98

Sheet Calculator
F1: © 2007-2019 Vertex42 LLC | I1: Strategies
A2: =HYPERLINK("https://www.vertex42.com/Calculators/debt-reduction-calculator.html","By Vertex42.com") -> By Vertex42.com | G2: =HYPERLINK("https://www.vertex42.com/Calculators/debt-reduction-calculator.html","HELP") -> HELP | I2: Snowball (Lowest Balance First)
I3: Avalanche (Highest Interest First)
B4: Balance Date: | C4: 45658 | I4: Stair-Stepper
I5: Order Entered In Table
B6: Creditor Information Table | I6: No Snowball
A7: Row | B7: Creditor | C7: Balance | D7: Interest | E7: Payment | F7: Custom | G7: Interest-only | I7: Custom - Highest First
A8: 1 | B8: Christmas Affirm | D8: 0 | G8: =ROUNDUP(OFFSET($C$7,ROW()-ROW($C$7),0,1,1)*OFFSET($D$7,ROW()-ROW($D$7),0,1,1)/12,2) -> 0 | I8: Custom - Lowest First
A9: =OFFSET(A9,-1,0,1,1)+1 -> 2 | B9: Christmas Affirm 1 | C9: 35.72 | D9: 0 | E9: 9.8 | G9: =ROUNDUP(OFFSET($C$7,ROW()-ROW($C$7),0,1,1)*OFFSET($D$7,ROW()-ROW($D$7),0,1,1)/12,2) -> 0
A10: =OFFSET(A10,-1,0,1,1)+1 -> 3 | B10: Christmas Affirm 2 | C10: 51.83 | D10: 0 | E10: 14.7 | G10: =ROUNDUP(OFFSET($C$7,ROW()-ROW($C$7),0,1,1)*OFFSET($D$7,ROW()-ROW($D$7),0,1,1)/12,2) -> 0
A11: =OFFSET(A11,-1,0,1,1)+1 -> 4 | B11: Christmas Affirm 3 | C11: 26.86 | D11: 0 | E11: 14.02 | G11: =ROUNDUP(OFFSET($C$7,ROW()-ROW($C$7),0,1,1)*OFFSET($D$7,ROW()-ROW($D$7),0,1,1)/12,2) -> 0
A12: =OFFSET(A12,-1,0,1,1)+1 -> 5 | B12: Christmas Affirm 4 | C12: 162.21 | D12: 0 | E12: 28.09 | G12: =ROUNDUP(OFFSET($C$7,ROW()-ROW($C$7),0,1,1)*OFFSET($D$7,ROW()-ROW($D$7),0,1,1)/12,2) -> 0
A13: =OFFSET(A13,-1,0,1,1)+1 -> 6 | B13: Christmas Affirm 5 | C13: 240.34 | D13: 0 | E13: 20.96 | G13: =ROUNDUP(OFFSET($C$7,ROW()-ROW($C$7),0,1,1)*OFFSET($D$7,ROW()-ROW($D$7),0,1,1)/12,2) -> 0
A14: =OFFSET(A14,-1,0,1,1)+1 -> 7 | B14: Tia Cap One | C14: 3200 | D14: 0.3174 | E14: 82 | G14: =ROUNDUP(OFFSET($C$7,ROW()-ROW($C$7),0,1,1)*OFFSET($D$7,ROW()-ROW($D$7),0,1,1)/12,2) -> 84.64
A15: =OFFSET(A15,-1,0,1,1)+1 -> 8 | B15: John Cap One | C15: 3800 | D15: 0.2974 | E15: 102 | G15: =ROUNDUP(OFFSET($C$7,ROW()-ROW($C$7),0,1,1)*OFFSET($D$7,ROW()-ROW($D$7),0,1,1)/12,2) -> 94.18
A16: =OFFSET(A16,-1,0,1,1)+1 -> 9 | B16: La'Kia | C16: 50000 | D16: 0.0928 | E16: 791.16 | G16: =ROUNDUP(OFFSET($C$7,ROW()-ROW($C$7),0,1,1)*OFFSET($D$7,ROW()-ROW($D$7),0,1,1)/12,2) -> 386.67
A17: =OFFSET(A17,-1,0,1,1)+1 -> 10 | B17: Tesla | C17: 38130 | D17: 0.11 | E17: 695.6 | G17: =ROUNDUP(OFFSET($C$7,ROW()-ROW($C$7),0,1,1)*OFFSET($D$7,ROW()-ROW($D$7),0,1,1)/12,2) -> 349.53 | J17: Black Tesla | M17: 695 | O17: 38130
A18: =OFFSET(A18,-1,0,1,1)+1 -> 11 | B18: Mortgage | C18: 181200 | D18: 0.0375 | E18: 1467.13 | G18: =ROUNDUP(OFFSET($C$7,ROW()-ROW($C$7),0,1,1)*OFFSET($D$7,ROW()-ROW($D$7),0,1,1)/12,2) -> 566.25
A19: =OFFSET(A19,-1,0,1,1)+1 -> 12 | B19: Upgrade Loan | C19: 15650.03 | D19: 0.18 | E19: 450.08 | G19: =ROUNDUP(OFFSET($C$7,ROW()-ROW($C$7),0,1,1)*OFFSET($D$7,ROW()-ROW($D$7),0,1,1)/12,2) -> 234.76
A20: =OFFSET(A20,-1,0,1,1)+1 -> 13 | B20: Emergency Loan | C20: 609.55 | D20: 0.2981 | E20: 35 | G20: =ROUNDUP(OFFSET($C$7,ROW()-ROW($C$7),0,1,1)*OFFSET($D$7,ROW()-ROW($D$7),0,1,1)/12,2) -> 15.15
A21: =OFFSET(A21,-1,0,1,1)+1 -> 14 | B21: James Braces | C21: 3100 | D21: 0.3 | E21: 206 | G21: =ROUNDUP(OFFSET($C$7,ROW()-ROW($C$7),0,1,1)*OFFSET($D$7,ROW()-ROW($D$7),0,1,1)/12,2) -> 77.5
A22: =OFFSET(A22,-1,0,1,1)+1 -> 15 | G22: =ROUNDUP(OFFSET($C$7,ROW()-ROW($C$7),0,1,1)*OFFSET($D$7,ROW()-ROW($D$7),0,1,1)/12,2) -> 0
A23: =OFFSET(A23,-1,0,1,1)+1 -> 16 | G23: =ROUNDUP(OFFSET($C$7,ROW()-ROW($C$7),0,1,1)*OFFSET($D$7,ROW()-ROW($D$7),0,1,1)/12,2) -> 0
A24: =OFFSET(A24,-1,0,1,1)+1 -> 17 | G24: =ROUNDUP(OFFSET($C$7,ROW()-ROW($C$7),0,1,1)*OFFSET($D$7,ROW()-ROW($D$7),0,1,1)/12,2) -> 0
A25: =OFFSET(A25,-1,0,1,1)+1 -> 18 | G25: =ROUNDUP(OFFSET($C$7,ROW()-ROW($C$7),0,1,1)*OFFSET($D$7,ROW()-ROW($D$7),0,1,1)/12,2) -> 0
A26: =OFFSET(A26,-1,0,1,1)+1 -> 19 | G26: =ROUNDUP(OFFSET($C$7,ROW()-ROW($C$7),0,1,1)*OFFSET($D$7,ROW()-ROW($D$7),0,1,1)/12,2) -> 0
A27: =OFFSET(A27,-1,0,1,1)+1 -> 20 | G27: =ROUNDUP(OFFSET($C$7,ROW()-ROW($C$7),0,1,1)*OFFSET($D$7,ROW()-ROW($D$7),0,1,1)/12,2) -> 0
A28: =OFFSET(A28,-1,0,1,1)+1 -> 21 | G28: =ROUNDUP(OFFSET($C$7,ROW()-ROW($C$7),0,1,1)*OFFSET($D$7,ROW()-ROW($D$7),0,1,1)/12,2) -> 0
A29: =OFFSET(A29,-1,0,1,1)+1 -> 22 | G29: =ROUNDUP(OFFSET($C$7,ROW()-ROW($C$7),0,1,1)*OFFSET($D$7,ROW()-ROW($D$7),0,1,1)/12,2) -> 0
A30: =OFFSET(A30,-1,0,1,1)+1 -> 23 | G30: =ROUNDUP(OFFSET($C$7,ROW()-ROW($C$7),0,1,1)*OFFSET($D$7,ROW()-ROW($D$7),0,1,1)/12,2) -> 0
A31: =OFFSET(A31,-1,0,1,1)+1 -> 24 | G31: =ROUNDUP(OFFSET($C$7,ROW()-ROW($C$7),0,1,1)*OFFSET($D$7,ROW()-ROW($D$7),0,1,1)/12,2) -> 0
A32: =OFFSET(A32,-1,0,1,1)+1 -> 25 | G32: =ROUNDUP(OFFSET($C$7,ROW()-ROW($C$7),0,1,1)*OFFSET($D$7,ROW()-ROW($D$7),0,1,1)/12,2) -> 0
A33: =OFFSET(A33,-1,0,1,1)+1 -> 26 | G33: =ROUNDUP(OFFSET($C$7,ROW()-ROW($C$7),0,1,1)*OFFSET($D$7,ROW()-ROW($D$7),0,1,1)/12,2) -> 0
... A46: =OFFSET(A46,-1,0,1,1)+1 -> 39 | G46: =ROUNDUP(OFFSET($C$7,ROW()-ROW($C$7),0,1,1)*OFFSET($D$7,ROW()-ROW($D$7),0,1,1)/12,2) -> 0
B47: Total: | C47: =SUM(C8:C30) -> 296206.54 | D47: Total: | E47: =SUM(E8:E30) -> 3916.54
A49: Monthly Payment | C49: 3862 | D49: =IF(NOT(Calculator!snowball),"Not Applicable (No Snowball)",IF(C49<=E47,"Too Low"," . ")) -> Too Low
A50: Initial Snowball
B52: Strategy: | C52: Snowball (Lowest Balance First) | F52: =MATCH(C52,I2:I8,0) -> 1
F53: =if(Calculator!strategy=5,false,true) -> TRUE
B54: Results are only estimates
...

Sheet PaymentSchedule
A1: Debt Snowball Payment Schedule | L1: © 2007-2019 Vertex42 LLC
A2: Results are only estimates. Only edit the yellow cells. | I2: =HYPERLINK("https://www.vertex42.com/Calculators/debt-reduction-calculator.html","https://www.vertex42.com/Calculators/debt-reduction-calculator.html") -> https://www.vertex42.com/Calculators/debt-reduction-calculator.html
A4: Strategy: | E4: {=INDEX(Calculator!I2:I8,Calculator!strategy)} -> Snowball (Lowest Balance First)
A5: Monthly Payment: | E5: =IF(NOT(Calculator!snowball),"Variable",Calculator!C49) -> 3862
AK6: row | AL6: col
A7: Creditor: | E7: {=IF(ISERROR(Order!B73),"",IF(ISBLANK(INDEX(Calculator!$B$8:$B$46,Order!B73))," - ",INDEX(Calculator!$B$8:$B$46,Order!B73)))} -> Christmas Affirm 3 | F7: {=IF(ISERROR(Order!C73),"",IF(ISBLANK(INDEX(Calculator!$B$8:$B$46,Order!C73))," - ",INDEX(Calculator!$B$8:$B$46,Order!C73)))} -> Christmas Affirm 1 | G7: {=IF(ISERROR(Order!D73),"",IF(ISBLANK(INDEX(Calculator!$B$8:$B$46,Order!D73))," - ",INDEX(Calculator!$B$8:$B$46,Order!D73)))} -> Christmas Affirm 2 | H7: {=IF(ISERROR(Order!E73),"",IF(ISBLANK(INDEX(Calculator!$B$8:$B$46,Order!E73))," - ",INDEX(Calculator!$B$8:$B$46,Order!E73)))} -> Christmas Affirm 4 | I7: {=IF(ISERROR(Order!F73),"",IF(ISBLANK(INDEX(Calculator!$B$8:$B$46,Order!F73))," - ",INDEX(Calculator!$B$8:$B$46,Order!F73)))} -> Christmas Affirm 5 | J7: {=IF(ISERROR(Order!G73),"",IF(ISBLANK(INDEX(Calculator!$B$8:$B$46,Order!G73))," - ",INDEX(Calculator!$B$8:$B$46,Order!G73)))} -> Emergency Loan | K7: {=IF(ISERROR(Order!H73),"",IF(ISBLANK(INDEX(Calculator!$B$8:$B$46,Order!H73))," - ",INDEX(Calculator!$B$8:$B$46,Order!H73)))} -> James Braces | L7: {=IF(ISERROR(Order!I73),"",IF(ISBLANK(INDEX(Calculator!$B$8:$B$46,Order!I73))," - ",INDEX(Calculator!$B$8:$B$46,Order!I73)))} -> Tia Cap One | ... AH7: {=IF(ISERROR(Order!AE73),"",IF(ISBLANK(INDEX(Calculator!$B$8:$B$46,Order!AE73))," - ",INDEX(Calculator!$B$8:$B$46,Order!AE73)))} | AK7: =MATCH(B21,$B$21:$B356,0) -> 1 | AL7: =MATCH('Jan 2025'!P28,$E19:$AG19,0) -> 8
A8: Balance: | E8: {=IF(ISERROR(Order!B73),0,INDEX(Calculator!$C$8:$C$46,Order!B73))} -> 26.86 | F8: {=IF(ISERROR(Order!C73),0,INDEX(Calculator!$C$8:$C$46,Order!C73))} -> 35.72 | G8: {=IF(ISERROR(Order!D73),0,INDEX(Calculator!$C$8:$C$46,Order!D73))} -> 51.83 | H8: {=IF(ISERROR(Order!E73),0,INDEX(Calculator!$C$8:$C$46,Order!E73))} -> 162.21 | I8: {=IF(ISERROR(Order!F73),0,INDEX(Calculator!$C$8:$C$46,Order!F73))} -> 240.34 | J8: {=IF(ISERROR(Order!G73),0,INDEX(Calculator!$C$8:$C$46,Order!G73))} -> 609.55 | K8: {=IF(ISERROR(Order!H73),0,INDEX(Calculator!$C$8:$C$46,Order!H73))} -> 3100 | L8: {=IF(ISERROR(Order!I73),0,INDEX(Calculator!$C$8:$C$46,Order!I73))} -> 3200 | ... AG8: {=IF(ISERROR(Order!AD73),0,INDEX(Calculator!$C$8:$C$46,Order!AD73))} -> 0 | AQ8: 204
A9: Rate: | E9: {=IF(ISERROR(Order!B73),0,INDEX(Calculator!$D$8:$D$46,Order!B73))} -> 0 | F9: {=IF(ISERROR(Order!C73),0,INDEX(Calculator!$D$8:$D$46,Order!C73))} -> 0 | G9: {=IF(ISERROR(Order!D73),0,INDEX(Calculator!$D$8:$D$46,Order!D73))} -> 0 | H9: {=IF(ISERROR(Order!E73),0,INDEX(Calculator!$D$8:$D$46,Order!E73))} -> 0 | I9: {=IF(ISERROR(Order!F73),0,INDEX(Calculator!$D$8:$D$46,Order!F73))} -> 0 | J9: {=IF(ISERROR(Order!G73),0,INDEX(Calculator!$D$8:$D$46,Order!G73))} -> 0.2981 | K9: {=IF(ISERROR(Order!H73),0,INDEX(Calculator!$D$8:$D$46,Order!H73))} -> 0.3 | L9: {=IF(ISERROR(Order!I73),0,INDEX(Calculator!$D$8:$D$46,Order!I73))} -> 0.3174 | ... AG9: {=IF(ISERROR(Order!AD73),0,INDEX(Calculator!$D$8:$D$46,Order!AD73))} -> 0 | AQ9: 176.71
A10: Base Payment: | E10: {=IF(ISERROR(Order!B73),0,INDEX(Calculator!$E$8:$E$46,Order!B73))} -> 14.02 | F10: {=IF(ISERROR(Order!C73),0,INDEX(Calculator!$E$8:$E$46,Order!C73))} -> 9.8 | G10: {=IF(ISERROR(Order!D73),0,INDEX(Calculator!$E$8:$E$46,Order!D73))} -> 14.7 | H10: {=IF(ISERROR(Order!E73),0,INDEX(Calculator!$E$8:$E$46,Order!E73))} -> 28.09 | I10: {=IF(ISERROR(Order!F73),0,INDEX(Calculator!$E$8:$E$46,Order!F73))} -> 20.96 | J10: {=IF(ISERROR(Order!G73),0,INDEX(Calculator!$E$8:$E$46,Order!G73))} -> 35 | K10: {=IF(ISERROR(Order!H73),0,INDEX(Calculator!$E$8:$E$46,Order!H73))} -> 206 | L10: {=IF(ISERROR(Order!I73),0,INDEX(Calculator!$E$8:$E$46,Order!I73))} -> 82 | ... AG10: {=IF(ISERROR(Order!AD73),0,INDEX(Calculator!$E$8:$E$46,Order!AD73))} -> 0
A11: Months to Pay Off: | E11: {=IF(E8>0,1+MAX((ROW(E21:E354)-ROW(E$21))*(E21:E354>0)),0)} -> 2 | F11: {=IF(F8>0,1+MAX((ROW(F21:F354)-ROW(F$21))*(F21:F354>0)),0)} -> 3 | G11: {=IF(G8>0,1+MAX((ROW(G21:G354)-ROW(G$21))*(G21:G354>0)),0)} -> 3 | H11: {=IF(H8>0,1+MAX((ROW(H21:H354)-ROW(H$21))*(H21:H354>0)),0)} -> 4 | I11: {=IF(I8>0,1+MAX((ROW(I21:I354)-ROW(I$21))*(I21:I354>0)),0)} -> 5 | J11: {=IF(J8>0,1+MAX((ROW(J21:J354)-ROW(J$21))*(J21:J354>0)),0)} -> 15 | K11: {=IF(K8>0,1+MAX((ROW(K21:K354)-ROW(K$21))*(K21:K354>0)),0)} -> 26 | L11: {=IF(L8>0,1+MAX((ROW(L21:L354)-ROW(L$21))*(L21:L354>0)),0)} -> 28 | ... AG11: {=IF(AG8>0,1+MAX((ROW(AG21:AG354)-ROW(AG$21))*(AG21:AG354>0)),0)} -> 0 | AK11: {=-INDEX($E$21:$AG356,MATCH(B21,$B$21:$B356,0),MATCH('Jan 2025'!P28,$E19:$AG19,0))} -> -82
A12: Month Paid Off: | E12: =IF(E8>0,INDEX($B$21:$B$354,E11),"") -> 45689 | F12: =IF(F8>0,INDEX($B$21:$B$354,F11),"") -> 45717 | G12: =IF(G8>0,INDEX($B$21:$B$354,G11),"") -> 45717 | H12: =IF(H8>0,INDEX($B$21:$B$354,H11),"") -> 45748 | I12: =IF(I8>0,INDEX($B$21:$B$354,I11),"") -> 45778 | J12: =IF(J8>0,INDEX($B$21:$B$354,J11),"") -> 46082 | K12: =IF(K8>0,INDEX($B$21:$B$354,K11),"") -> 46419 | L12: =IF(L8>0,INDEX($B$21:$B$354,L11),"") -> 46478 | ... AG12: =IF(AG8>0,INDEX($B$21:$B$354,AG11),"")
A13: Total Interest: | E13: =IF(E320=0,SUM(BN21:BN354),NA()) -> 0 | F13: =IF(F320=0,SUM(BO21:BO354),NA()) -> 0 | G13: =IF(G320=0,SUM(BP21:BP354),NA()) -> 0 | H13: =IF(H320=0,SUM(BQ21:BQ354),NA()) -> 0 | I13: =IF(I320=0,SUM(BR21:BR354),NA()) -> 0 | J13: =IF(J320=0,SUM(BS21:BS354),NA()) -> 152.09 | K13: =IF(K320=0,SUM(BT21:BT354),NA()) -> 1248.19 | L13: =IF(L320=0,SUM(BU21:BU354),NA()) -> 2409.27 | ... AG13: =IF(AG320=0,SUM(CP21:CP354),NA()) -> 0
A14: Error Code: | E14: =IF(E320>0,">"&$A$320&" Payments"," . ") -> . | F14: =IF(F320>0,">"&$A$320&" Payments"," . ") -> . | G14: =IF(G320>0,">"&$A$320&" Payments"," . ") -> . | H14: =IF(H320>0,">"&$A$320&" Payments"," . ") -> . | I14: =IF(I320>0,">"&$A$320&" Payments"," . ") -> . | J14: =IF(J320>0,">"&$A$320&" Payments"," . ") -> . | K14: =IF(K320>0,">"&$A$320&" Payments"," . ") -> . | L14: =IF(L320>0,">"&$A$320&" Payments"," . ") -> . | ... AG14: =IF(AG320>0,">"&$A$320&" Payments"," . ") -> .
A16: Total Interest: | E16: =SUM(E13:AG13) -> 81410.12
E18: Monthly Payments | AI18: Balance AFTER Payment | BN18: Interest | CT18: Payment Before Snowball
A19: No. | B19: Month | C19: Snowball | D19: Additional | E19: =E7 -> Christmas Affirm 3 | F19: =F7 -> Christmas Affirm 1 | G19: =G7 -> Christmas Affirm 2 | H19: =H7 -> Christmas Affirm 4 | I19: =I7 -> Christmas Affirm 5 | J19: =J7 -> Emergency Loan | K19: =K7 -> James Braces | L19: =L7 -> Tia Cap One | ... AG19: =AG7 | AH19: Total Balance | AI19: =E19 -> Christmas Affirm 3 | AJ19: =F19 -> Christmas Affirm 1 | AK19: =G19 -> Christmas Affirm 2 | AL19: =H19 -> Christmas Affirm 4 | AM19: =I19 -> Christmas Affirm 5 | AN19: =J19 -> Emergency Loan | AO19: =K19 -> James Braces | AP19: =L19 -> Tia Cap One | ... BK19: =AG19 | BL19: Total Balance | BN19: =E19 -> Christmas Affirm 3 | BO19: =F19 -> Christmas Affirm 1 | BP19: =G19 -> Christmas Affirm 2 | BQ19: =H19 -> Christmas Affirm 4 | BR19: =I19 -> Christmas Affirm 5 | BS19: =J19 -> Emergency Loan | BT19: =K19 -> James Braces | BU19: =L19 -> Tia Cap One | ... CP19: =AG19 | CR19: TOTAL | CT19: =E19 -> Christmas Affirm 3 | CU19: =F19 -> Christmas Affirm 1 | CV19: =G19 -> Christmas Affirm 2 | CW19: =H19 -> Christmas Affirm 4 | CX19: =I19 -> Christmas Affirm 5 | CY19: =J19 -> Emergency Loan | CZ19: =K19 -> James Braces | DA19: =L19 -> Tia Cap One | ... DV19: =AG19 | DY19: TOTAL | EA19: Extra Payment
AH20: =SUM(AI20:BK20) -> 296206.54 | AI20: =E8 -> 26.86 | AJ20: =F8 -> 35.72 | AK20: =G8 -> 51.83 | AL20: =H8 -> 162.21 | AM20: =I8 -> 240.34 | AN20: =J8 -> 609.55 | AO20: =K8 -> 3100 | AP20: =L8 -> 3200 | ... BK20: =AG8 -> 0 | BL20: =SUM(AI20:BK20) -> 296206.54 | EA20: =E7 -> Christmas Affirm 3 | EB20: =F7 -> Christmas Affirm 1 | EC20: =G7 -> Christmas Affirm 2 | ED20: =H7 -> Christmas Affirm 4 | EE20: =I7 -> Christmas Affirm 5 | EF20: =J7 -> Emergency Loan | EG20: =K7 -> James Braces | EH20: =L7 -> Tia Cap One | ... FE20: =AI7
A21: =IF(SUM(AI20:BK20)<=0,"",A20+1) -> 1 | B21: 45658 | C21: =IF(A21="","",IF(Calculator!snowball,IF(($E$5-DY21)<0,0,$E$5-DY21),0)+D21) -> 0 | E21: =CT21+EA22 -> 14.02 | F21: =CU21+EB22 -> 9.8 | G21: =CV21+EC22 -> 14.7 | H21: =CW21+ED22 -> 28.09 | I21: =CX21+EE22 -> 20.96 | J21: =CY21+EF22 -> 35 | L21: =DA21+EH22 -> 82 | M21: =DB21+EI22 -> 102 | N21: =DC21+EJ22 -> 450.08 | P21: =DE21+EL22 -> 791.16 | Q21: 1560.81 | R21: =DG21+EN22 -> 0 | S21: =DH21+EO22 -> 0 | T21: =DI21+EP22 -> 0 | U21: =DJ21+EQ22 -> 0 | V21: =DK21+ER22 -> 0 | W21: =DL21+ES22 -> 0 | X21: =DM21+ET22 -> 0 | Y21: =DN21+EU22 -> 0 | ... AG21: =DV21+FC22 -> 0 | AH21: =SUM(AI21:BK21) -> 294689.86 | AI21: =IF(E$8=0,0,ROUND(AI20-(E21-BN21),2)) -> 12.84 | AJ21: =IF(F$8=0,0,ROUND(AJ20-(F21-BO21),2)) -> 25.92 | AK21: =IF(G$8=0,0,ROUND(AK20-(G21-BP21),2)) -> 37.13 | AL21: =IF(H$8=0,0,ROUND(AL20-(H21-BQ21),2)) -> 134.12 | AM21: =IF(I$8=0,0,ROUND(AM20-(I21-BR21),2)) -> 219.38 | AN21: =IF(J$8=0,0,ROUND(AN20-(J21-BS21),2)) -> 589.69 | AO21: =IF(K$8=0,0,ROUND(AO20-(K21-BT21),2)) -> 3177.5 | AP21: =IF(L$8=0,0,ROUND(AP20-(L21-BU21),2)) -> 3202.64 | ... AS21: =IF(O$8=0,0,ROUND(AS20-(O21-BX21),2)) -> 38479.53 | AT21: =IF(P$8=0,0,ROUND(AT20-(P21-BX21),2)) -> 49558.37 | AU21: =IF(Q$8=0,0,ROUND(AU20-(Q21-BY21),2)) -> 180025.86 | AV21: =IF(R$8=0,0,ROUND(AV20-(R21-BZ21),2)) -> 0 | AW21: =IF(S$8=0,0,ROUND(AW20-(S21-CA21),2)) -> 0 | AX21: =IF(T$8=0,0,ROUND(AX20-(T21-CB21),2)) -> 0 | AY21: =IF(U$8=0,0,ROUND(AY20-(U21-CC21),2)) -> 0 | AZ21: =IF(V$8=0,0,ROUND(AZ20-(V21-CD21),2)) -> 0 | BA21: =IF(W$8=0,0,ROUND(BA20-(W21-CE21),2)) -> 0 | ... BK21: =IF(AG$8=0,0,ROUND(BK20-(AG21-CO21),2)) -> 0 | BL21: =SUM(AI21:BK21) -> 294689.86 | BN21: =ROUND(AI20*E$9/12,2) -> 0 | BO21: =ROUND(AJ20*F$9/12,2) -> 0 | BP21: =ROUND(AK20*G$9/12,2) -> 0 | BQ21: =ROUND(AL20*H$9/12,2) -> 0 | BR21: =ROUND(AM20*I$9/12,2) -> 0 | BS21: =ROUND(AN20*J$9/12,2) -> 15.14 | BT21: =ROUND(AO20*K$9/12,2) -> 77.5 | BU21: =ROUND(AP20*L$9/12,2) -> 84.64 | ... CP21: =ROUND(BK20*AG$9/12,2) -> 0 | CR21: =SUM(BN21:CP21) -> 1808.66 | CT21: =IF(AI20>0,IF((AI20+BN21)<E$10,AI20+BN21,E$10),0) -> 14.02 | CU21: =IF(AJ20>0,IF((AJ20+BO21)<F$10,AJ20+BO21,F$10),0) -> 9.8 | CV21: =IF(AK20>0,IF((AK20+BP21)<G$10,AK20+BP21,G$10),0) -> 14.7 | CW21: =IF(AL20>0,IF((AL20+BQ21)<H$10,AL20+BQ21,H$10),0) -> 28.09 | CX21: =IF(AM20>0,IF((AM20+BR21)<I$10,AM20+BR21,I$10),0) -> 20.96 | CY21: =IF(AN20>0,IF((AN20+BS21)<J$10,AN20+BS21,J$10),0) -> 35 | CZ21: =IF(AO20>0,IF((AO20+BT21)<K$10,AO20+BT21,K$10),0) -> 206 | DA21: =IF(AP20>0,IF((AP20+BU21)<L$10,AP20+BU21,L$10),0) -> 82 | ... DX21: =IF(BM20>0,IF((BM20+CR21)<AI$10,BM20+CR21,AI$10),0) -> 0 | DY21: =SUM(CT21:DX21) -> 3916.54
A22: =IF(SUM(AI21:BK21)<=0,"",A21+1) -> 2 | B22: 45689 | C22: 0 | E22: =CT22+EA23 -> 12.84 | F22: =CU22+EB23 -> 9.8 | G22: =CV22+EC23 -> 14.7 | H22: =CW22+ED23 -> 28.09 | I22: =CX22+EE23 -> 20.96 | J22: =CY22+EF23 -> 35 | L22: =DA22+EH23 -> 82 | M22: =DB22+EI23 -> 102 | N22: =DC22+EJ23 -> 450.08 | P22: =DE22+EL23 -> 791.16 | Q22: 1560.81 | R22: =DG22+EN23 -> 0 | S22: =DH22+EO23 -> 0 | T22: =DI22+EP23 -> 0 | U22: =DJ22+EQ23 -> 0 | V22: =DK22+ER23 -> 0 | W22: =DL22+ES23 -> 0 | X22: =DM22+ET23 -> 0 | Y22: =DN22+EU23 -> 0 | ... AG22: =DV22+FC23 -> 0 | AH22: =SUM(AI22:BK22) -> 293175.43 | AI22: =IF(E$8=0,0,ROUND(AI21-(E22-BN22),2)) -> 0 | AJ22: =IF(F$8=0,0,ROUND(AJ21-(F22-BO22),2)) -> 16.12 | AK22: =IF(G$8=0,0,ROUND(AK21-(G22-BP22),2)) -> 22.43 | AL22: =IF(H$8=0,0,ROUND(AL21-(H22-BQ22),2)) -> 106.03 | AM22: =IF(I$8=0,0,ROUND(AM21-(I22-BR22),2)) -> 198.42 | AN22: =IF(J$8=0,0,ROUND(AN21-(J22-BS22),2)) -> 569.34 | AO22: =IF(K$8=0,0,ROUND(AO21-(K22-BT22),2)) -> 3256.94 | AP22: =IF(L$8=0,0,ROUND(AP21-(L22-BU22),2)) -> 3205.35 | ... AS22: =IF(O$8=0,0,ROUND(AS21-(O22-BX22),2)) -> 38832.26 | AT22: =IF(P$8=0,0,ROUND(AT21-(P22-BX22),2)) -> 49119.94 | AU22: =IF(Q$8=0,0,ROUND(AU21-(Q22-BY22),2)) -> 178848.3 | AV22: =IF(R$8=0,0,ROUND(AV21-(R22-BZ22),2)) -> 0 | AW22: =IF(S$8=0,0,ROUND(AW21-(S22-CA22),2)) -> 0 | AX22: =IF(T$8=0,0,ROUND(AX21-(T22-CB22),2)) -> 0 | AY22: =IF(U$8=0,0,ROUND(AY21-(U22-CC22),2)) -> 0 | AZ22: =IF(V$8=0,0,ROUND(AZ21-(V22-CD22),2)) -> 0 | BA22: =IF(W$8=0,0,ROUND(BA21-(W22-CE22),2)) -> 0 | ... BK22: =IF(AG$8=0,0,ROUND(BK21-(AG22-CO22),2)) -> 0 | BL22: =SUM(AI22:BK22) -> 293175.43 | BN22: =ROUND(AI21*E$9/12,2) -> 0 | BO22: =ROUND(AJ21*F$9/12,2) -> 0 | BP22: =ROUND(AK21*G$9/12,2) -> 0 | BQ22: =ROUND(AL21*H$9/12,2) -> 0 | BR22: =ROUND(AM21*I$9/12,2) -> 0 | BS22: =ROUND(AN21*J$9/12,2) -> 14.65 | BT22: =ROUND(AO21*K$9/12,2) -> 79.44 | BU22: =ROUND(AP21*L$9/12,2) -> 84.71 | ... CP22: =ROUND(BK21*AG$9/12,2) -> 0 | CR22: =SUM(BN22:CP22) -> 1802.86 | CT22: =IF(AI21>0,IF((AI21+BN22)<E$10,AI21+BN22,E$10),0) -> 12.84 | CU22: =IF(AJ21>0,IF((AJ21+BO22)<F$10,AJ21+BO22,F$10),0) -> 9.8 | CV22: =IF(AK21>0,IF((AK21+BP22)<G$10,AK21+BP22,G$10),0) -> 14.7 | CW22: =IF(AL21>0,IF((AL21+BQ22)<H$10,AL21+BQ22,H$10),0) -> 28.09 | CX22: =IF(AM21>0,IF((AM21+BR22)<I$10,AM21+BR22,I$10),0) -> 20.96 | CY22: =IF(AN21>0,IF((AN21+BS22)<J$10,AN21+BS22,J$10),0) -> 35 | CZ22: =IF(AO21>0,IF((AO21+BT22)<K$10,AO21+BT22,K$10),0) -> 206 | DA22: =IF(AP21>0,IF((AP21+BU22)<L$10,AP21+BU22,L$10),0) -> 82 | ... DX22: =IF(BM21>0,IF((BM21+CR22)<AI$10,BM21+CR22,AI$10),0) -> 0 | DY22: =SUM(CT22:DX22) -> 3915.36 | EA22: =IF(AI20<=0,0,IF(CT21+$C21>AI20+BN21,AI20+BN21-CT21,$C21)) -> 0 | EB22: =IF(AJ20<=0,0,IF($C21<=SUM($EA22:EA22),0,IF(CU21+$C21-SUM($EA22:EA22)>AJ20+BO21,AJ20+BO21-CU21,$C21-SUM($EA22:EA22)))) -> 0 | EC22: =IF(AK20<=0,0,IF($C21<=SUM($EA22:EB22),0,IF(CV21+$C21-SUM($EA22:EB22)>AK20+BP21,AK20+BP21-CV21,$C21-SUM($EA22:EB22)))) -> 0 | ED22: =IF(AL20<=0,0,IF($C21<=SUM($EA22:EC22),0,IF(CW21+$C21-SUM($EA22:EC22)>AL20+BQ21,AL20+BQ21-CW21,$C21-SUM($EA22:EC22)))) -> 0 | EE22: =IF(AM20<=0,0,IF($C21<=SUM($EA22:ED22),0,IF(CX21+$C21-SUM($EA22:ED22)>AM20+BR21,AM20+BR21-CX21,$C21-SUM($EA22:ED22)))) -> 0 | EF22: =IF(AN20<=0,0,IF($C21<=SUM($EA22:EE22),0,IF(CY21+$C21-SUM($EA22:EE22)>AN20+BS21,AN20+BS21-CY21,$C21-SUM($EA22:EE22)))) -> 0 | EG22: =IF(AO20<=0,0,IF($C21<=SUM($EA22:EF22),0,IF(CZ21+$C21-SUM($EA22:EF22)>AO20+BT21,AO20+BT21-CZ21,$C21-SUM($EA22:EF22)))) -> 0 | EH22: =IF(AP20<=0,0,IF($C21<=SUM($EA22:EG22),0,IF(DA21+$C21-SUM($EA22:EG22)>AP20+BU21,AP20+BU21-DA21,$C21-SUM($EA22:EG22)))) -> 0 | EI22: =IF(AQ20<=0,0,IF($C21<=SUM($EA22:EH22),0,IF(DB21+$C21-SUM($EA22:EH22)>AQ20+BV21,AQ20+BV21-DB21,$C21-SUM($EA22:EH22)))) -> 0 | ... FC22: =IF(BK20<=0,0,IF($C21<=SUM($EA22:FB22),0,IF(DV21+$C21-SUM($EA22:FB22)>BK20+CP21,BK20+CP21-DV21,$C21-SUM($EA22:FB22)))) -> 0
A23: =IF(SUM(AI22:BK22)<=0,"",A22+1) -> 3 | B23: 45717 | C23: =IF(A23="","",IF(Calculator!snowball,IF(($E$5-DY23)<0,0,$E$5-DY23),0)+D23) -> 0 | E23: =CT23+EA24 -> 0 | F23: 16.12 | G23: 22.43 | H23: =CW23+ED24 -> 28.09 | I23: =CX23+EE24 -> 20.96 | J23: =CY23+EF24 -> 35 | K23: 600 | L23: =DA23+EH24 -> 82 | M23: =DB23+EI24 -> 102 | N23: =DC23+EJ24 -> 450.08 | P23: =DE23+EL24 -> 791.16 | Q23: 1487.37 | R23: =DG23+EN24 -> 0 | S23: =DH23+EO24 -> 0 | T23: =DI23+EP24 -> 0 | U23: =DJ23+EQ24 -> 0 | V23: =DK23+ER24 -> 0 | W23: =DL23+ES24 -> 0 | X23: =DM23+ET24 -> 0 | Y23: =DN23+EU24 -> 0 | ... AG23: =DV23+FC24 -> 0 | AH23: =SUM(AI23:BK23) -> 291134.36 | AI23: =IF(E$8=0,0,ROUND(AI22-(E23-BN23),2)) -> 0 | AJ23: 0 | AK23: 0 | AL23: =IF(H$8=0,0,ROUND(AL22-(H23-BQ23),2)) -> 77.94 | AM23: =IF(I$8=0,0,ROUND(AM22-(I23-BR23),2)) -> 177.46 | AN23: =IF(J$8=0,0,ROUND(AN22-(J23-BS23),2)) -> 548.48 | AO23: =IF(K$8=0,0,ROUND(AO22-(K23-BT23),2)) -> 2738.36 | AP23: =IF(L$8=0,0,ROUND(AP22-(L23-BU23),2)) -> 3208.13 | AQ23: =IF(M$8=0,0,ROUND(AQ22-(M23-BV23),2)) -> 3775.94 | AR23: =IF(N$8=0,0,ROUND(AR22-(N23-BW23),2)) -> 14994.3 | AS23: =IF(O$8=0,0,ROUND(AS22-(O23-BX23),2)) -> 39188.22 | AT23: =IF(P$8=0,0,ROUND(AT22-(P23-BX23),2)) -> 48684.74 | AU23: =IF(Q$8=0,0,ROUND(AU22-(Q23-BY23),2)) -> 177740.79 | AV23: =IF(R$8=0,0,ROUND(AV22-(R23-BZ23),2)) -> 0 | AW23: =IF(S$8=0,0,ROUND(AW22-(S23-CA23),2)) -> 0 | AX23: =IF(T$8=0,0,ROUND(AX22-(T23-CB23),2)) -> 0 | AY23: =IF(U$8=0,0,ROUND(AY22-(U23-CC23),2)) -> 0 | AZ23: =IF(V$8=0,0,ROUND(AZ22-(V23-CD23),2)) -> 0 | BA23: =IF(W$8=0,0,ROUND(BA22-(W23-CE23),2)) -> 0 | ... BK23: =IF(AG$8=0,0,ROUND(BK22-(AG23-CO23),2)) -> 0 | BL23: =SUM(AI23:BK23) -> 291134.36 | BN23: =ROUND(AI22*E$9/12,2) -> 0 | BO23: =ROUND(AJ22*F$9/12,2) -> 0 | BP23: =ROUND(AK22*G$9/12,2) -> 0 | BQ23: =ROUND(AL22*H$9/12,2) -> 0 | BR23: =ROUND(AM22*I$9/12,2) -> 0 | BS23: =ROUND(AN22*J$9/12,2) -> 14.14 | BT23: =ROUND(AO22*K$9/12,2) -> 81.42 | BU23: =ROUND(AP22*L$9/12,2) -> 84.78 | ... CP23: =ROUND(BK22*AG$9/12,2) -> 0 | CR23: =SUM(BN23:CP23) -> 1797.08 | CT23: =IF(AI22>0,IF((AI22+BN23)<E$10,AI22+BN23,E$10),0) -> 0 | CU23: =IF(AJ22>0,IF((AJ22+BO23)<F$10,AJ22+BO23,F$10),0) -> 9.8 | CV23: =IF(AK22>0,IF((AK22+BP23)<G$10,AK22+BP23,G$10),0) -> 14.7 | CW23: =IF(AL22>0,IF((AL22+BQ23)<H$10,AL22+BQ23,H$10),0) -> 28.09 | CX23: =IF(AM22>0,IF((AM22+BR23)<I$10,AM22+BR23,I$10),0) -> 20.96 | CY23: =IF(AN22>0,IF((AN22+BS23)<J$10,AN22+BS23,J$10),0) -> 35 | CZ23: =IF(AO22>0,IF((AO22+BT23)<K$10,AO22+BT23,K$10),0) -> 206 | DA23: =IF(AP22>0,IF((AP22+BU23)<L$10,AP22+BU23,L$10),0) -> 82 | ... DX23: =IF(BM22>0,IF((BM22+CR23)<AI$10,BM22+CR23,AI$10),0) -> 0 | DY23: =SUM(CT23:DX23) -> 3902.52 | EA23: =IF(AI21<=0,0,IF(CT22+$C22>AI21+BN22,AI21+BN22-CT22,$C22)) -> 0 | EB23: =IF(AJ21<=0,0,IF($C22<=SUM($EA23:EA23),0,IF(CU22+$C22-SUM($EA23:EA23)>AJ21+BO22,AJ21+BO22-CU22,$C22-SUM($EA23:EA23)))) -> 0 | EC23: =IF(AK21<=0,0,IF($C22<=SUM($EA23:EB23),0,IF(CV22+$C22-SUM($EA23:EB23)>AK21+BP22,AK21+BP22-CV22,$C22-SUM($EA23:EB23)))) -> 0 | ED23: =IF(AL21<=0,0,IF($C22<=SUM($EA23:EC23),0,IF(CW22+$C22-SUM($EA23:EC23)>AL21+BQ22,AL21+BQ22-CW22,$C22-SUM($EA23:EC23)))) -> 0 | EE23: =IF(AM21<=0,0,IF($C22<=SUM($EA23:ED23),0,IF(CX22+$C22-SUM($EA23:ED23)>AM21+BR22,AM21+BR22-CX22,$C22-SUM($EA23:ED23)))) -> 0 | EF23: =IF(AN21<=0,0,IF($C22<=SUM($EA23:EE23),0,IF(CY22+$C22-SUM($EA23:EE23)>AN21+BS22,AN21+BS22-CY22,$C22-SUM($EA23:EE23)))) -> 0 | EG23: =IF(AO21<=0,0,IF($C22<=SUM($EA23:EF23),0,IF(CZ22+$C22-SUM($EA23:EF23)>AO21+BT22,AO21+BT22-CZ22,$C22-SUM($EA23:EF23)))) -> 0 | EH23: =IF(AP21<=0,0,IF($C22<=SUM($EA23:EG23),0,IF(DA22+$C22-SUM($EA23:EG23)>AP21+BU22,AP21+BU22-DA22,$C22-SUM($EA23:EG23)))) -> 0 | EI23: =IF(AQ21<=0,0,IF($C22<=SUM($EA23:EH23),0,IF(DB22+$C22-SUM($EA23:EH23)>AQ21+BV22,AQ21+BV22-DB22,$C22-SUM($EA23:EH23)))) -> 0 | ... FC23: =IF(BK21<=0,0,IF($C22<=SUM($EA23:FB23),0,IF(DV22+$C22-SUM($EA23:FB23)>BK21+CP22,BK21+CP22-DV22,$C22-SUM($EA23:FB23)))) -> 0
A24: =IF(SUM(AI23:BK23)<=0,"",A23+1) -> 4 | B24: 45748 | C24: =IF(A24="","",IF(Calculator!snowball,IF(($E$5-DY24)<0,0,$E$5-DY24),0)+D24) -> 0 | E24: =CT24+EA25 -> 0 | F24: =CU24+EB25 -> 0 | G24: =CV24+EC25 -> 0 | H24: 78.85 | I24: =CX24+EE25 -> 20.96 | J24: 35 | K24: =CZ24+EG25 -> 206 | L24: 83 | M24: 109 | N24: =DC24+EJ25 -> 450.08 | P24: =DE24+EL25 -> 791.16 | Q24: 1487.37 | R24: =DG24+EN25 -> 0 | S24: =DH24+EO25 -> 0 | T24: =DI24+EP25 -> 0 | U24: =DJ24+EQ25 -> 0 | V24: =DK24+ER25 -> 0 | W24: =DL24+ES25 -> 0 | X24: =DM24+ET25 -> 0 | Y24: =DN24+EU25 -> 0 | ... AG24: =DV24+FC25 -> 0 | AH24: =SUM(AI24:BK24) -> 289454.25 | AI24: =IF(E$8=0,0,ROUND(AI23-(E24-BN24),2)) -> 0 | AJ24: =IF(F$8=0,0,ROUND(AJ23-(F24-BO24),2)) -> 0 | AK24: =IF(G$8=0,0,ROUND(AK23-(G24-BP24),2)) -> 0 | AL24: 0 | AM24: =IF(I$8=0,0,ROUND(AM23-(I24-BR24),2)) -> 156.5 | AN24: =IF(J$8=0,0,ROUND(AN23-(J24-BS24),2)) -> 527.11 | AO24: =IF(K$8=0,0,ROUND(AO23-(K24-BT24),2)) -> 2600.82 | AP24: =IF(L$8=0,0,ROUND(AP23-(L24-BU24),2)) -> 3209.99 | AQ24: =IF(M$8=0,0,ROUND(AQ23-(M24-BV24),2)) -> 3760.52 | AR24: =IF(N$8=0,0,ROUND(AR23-(N24-BW24),2)) -> 14769.13 | AS24: =IF(O$8=0,0,ROUND(AS23-(O24-BX24),2)) -> 39547.45 | AT24: =IF(P$8=0,0,ROUND(AT23-(P24-BX24),2)) -> 48252.81 | AU24: =IF(Q$8=0,0,ROUND(AU23-(Q24-BY24),2)) -> 176629.92 | AV24: =IF(R$8=0,0,ROUND(AV23-(R24-BZ24),2)) -> 0 | AW24: =IF(S$8=0,0,ROUND(AW23-(S24-CA24),2)) -> 0 | AX24: =IF(T$8=0,0,ROUND(AX23-(T24-CB24),2)) -> 0 | AY24: =IF(U$8=0,0,ROUND(AY23-(U24-CC24),2)) -> 0 | AZ24: =IF(V$8=0,0,ROUND(AZ23-(V24-CD24),2)) -> 0 | BA24: =IF(W$8=0,0,ROUND(BA23-(W24-CE24),2)) -> 0 | ... BK24: =IF(AG$8=0,0,ROUND(BK23-(AG24-CO24),2)) -> 0 | BL24: =SUM(AI24:BK24) -> 289454.25 | BN24: =ROUND(AI23*E$9/12,2) -> 0 | BO24: =ROUND(AJ23*F$9/12,2) -> 0 | BP24: =ROUND(AK23*G$9/12,2) -> 0 | BQ24: =ROUND(AL23*H$9/12,2) -> 0 | BR24: =ROUND(AM23*I$9/12,2) -> 0 | BS24: =ROUND(AN23*J$9/12,2) -> 13.63 | BT24: =ROUND(AO23*K$9/12,2) -> 68.46 | BU24: =ROUND(AP23*L$9/12,2) -> 84.86 | ... CP24: =ROUND(BK23*AG$9/12,2) -> 0 | CR24: =SUM(BN24:CP24) -> 1776.61 | CT24: =IF(AI23>0,IF((AI23+BN24)<E$10,AI23+BN24,E$10),0) -> 0 | CU24: =IF(AJ23>0,IF((AJ23+BO24)<F$10,AJ23+BO24,F$10),0) -> 0 | CV24: =IF(AK23>0,IF((AK23+BP24)<G$10,AK23+BP24,G$10),0) -> 0 | CW24: =IF(AL23>0,IF((AL23+BQ24)<H$10,AL23+BQ24,H$10),0) -> 28.09 | CX24: =IF(AM23>0,IF((AM23+BR24)<I$10,AM23+BR24,I$10),0) -> 20.96 | CY24: =IF(AN23>0,IF((AN23+BS24)<J$10,AN23+BS24,J$10),0) -> 35 | CZ24: =IF(AO23>0,IF((AO23+BT24)<K$10,AO23+BT24,K$10),0) -> 206 | DA24: =IF(AP23>0,IF((AP23+BU24)<L$10,AP23+BU24,L$10),0) -> 82 | ... DX24: =IF(BM23>0,IF((BM23+CR24)<AI$10,BM23+CR24,AI$10),0) -> 0 | DY24: =SUM(CT24:DX24) -> 3878.02 | EA24: =IF(AI22<=0,0,IF(CT23+$C23>AI22+BN23,AI22+BN23-CT23,$C23)) -> 0 | EB24: =IF(AJ22<=0,0,IF($C23<=SUM($EA24:EA24),0,IF(CU23+$C23-SUM($EA24:EA24)>AJ22+BO23,AJ22+BO23-CU23,$C23-SUM($EA24:EA24)))) -> 0 | EC24: =IF(AK22<=0,0,IF($C23<=SUM($EA24:EB24),0,IF(CV23+$C23-SUM($EA24:EB24)>AK22+BP23,AK22+BP23-CV23,$C23-SUM($EA24:EB24)))) -> 0 | ED24: =IF(AL22<=0,0,IF($C23<=SUM($EA24:EC24),0,IF(CW23+$C23-SUM($EA24:EC24)>AL22+BQ23,AL22+BQ23-CW23,$C23-SUM($EA24:EC24)))) -> 0 | EE24: =IF(AM22<=0,0,IF($C23<=SUM($EA24:ED24),0,IF(CX23+$C23-SUM($EA24:ED24)>AM22+BR23,AM22+BR23-CX23,$C23-SUM($EA24:ED24)))) -> 0 | EF24: =IF(AN22<=0,0,IF($C23<=SUM($EA24:EE24),0,IF(CY23+$C23-SUM($EA24:EE24)>AN22+BS23,AN22+BS23-CY23,$C23-SUM($EA24:EE24)))) -> 0 | EG24: =IF(AO22<=0,0,IF($C23<=SUM($EA24:EF24),0,IF(CZ23+$C23-SUM($EA24:EF24)>AO22+BT23,AO22+BT23-CZ23,$C23-SUM($EA24:EF24)))) -> 0 | EH24: =IF(AP22<=0,0,IF($C23<=SUM($EA24:EG24),0,IF(DA23+$C23-SUM($EA24:EG24)>AP22+BU23,AP22+BU23-DA23,$C23-SUM($EA24:EG24)))) -> 0 | EI24: =IF(AQ22<=0,0,IF($C23<=SUM($EA24:EH24),0,IF(DB23+$C23-SUM($EA24:EH24)>AQ22+BV23,AQ22+BV23-DB23,$C23-SUM($EA24:EH24)))) -> 0 | ... FC24: =IF(BK22<=0,0,IF($C23<=SUM($EA24:FB24),0,IF(DV23+$C23-SUM($EA24:FB24)>BK22+CP23,BK22+CP23-DV23,$C23-SUM($EA24:FB24)))) -> 0
A25: =IF(SUM(AI24:BK24)<=0,"",A24+1) -> 5 | B25: 45778 | C25: =IF(A25="","",IF(Calculator!snowball,IF(($E$5-DY25)<0,0,$E$5-DY25),0)+D25) -> 12.07 | E25: =CT25+EA26 -> 0 | F25: =CU25+EB26 -> 0 | G25: =CV25+EC26 -> 0 | H25: =CW25+ED26 -> 0 | I25: 156.5 | J25: =CY25+EF26 -> 35 | K25: =CZ25+EG26 -> 206 | L25: 83 | M25: 126 | N25: =DC25+EJ26 -> 450.08 | P25: =DE25+EL26 -> 791.16 | Q25: 1487.37 | R25: =DG25+EN26 -> 0 | S25: =DH25+EO26 -> 0 | T25: =DI25+EP26 -> 0 | U25: =DJ25+EQ26 -> 0 | V25: =DK25+ER26 -> 0 | W25: =DL25+ES26 -> 0 | X25: =DM25+ET26 -> 0 | Y25: =DN25+EU26 -> 0 | ... AG25: =DV25+FC26 -> 0 | AH25: =SUM(AI25:BK25) -> 287695.09 | AI25: =IF(E$8=0,0,ROUND(AI24-(E25-BN25),2)) -> 0 | AJ25: =IF(F$8=0,0,ROUND(AJ24-(F25-BO25),2)) -> 0 | AK25: =IF(G$8=0,0,ROUND(AK24-(G25-BP25),2)) -> 0 | AL25: =IF(H$8=0,0,ROUND(AL24-(H25-BQ25),2)) -> 0 | AM25: 0 | AN25: =IF(J$8=0,0,ROUND(AN24-(J25-BS25),2)) -> 505.2 | AO25: =IF(K$8=0,0,ROUND(AO24-(K25-BT25),2)) -> 2459.84 | AP25: =IF(L$8=0,0,ROUND(AP24-(L25-BU25),2)) -> 3211.89 | AQ25: =IF(M$8=0,0,ROUND(AQ24-(M25-BV25),2)) -> 3727.72 | AR25: =IF(N$8=0,0,ROUND(AR24-(N25-BW25),2)) -> 14540.59 | AS25: =IF(O$8=0,0,ROUND(AS24-(O25-BX25),2)) -> 39909.97 | AT25: =IF(P$8=0,0,ROUND(AT24-(P25-BX25),2)) -> 47824.17 | AU25: =IF(Q$8=0,0,ROUND(AU24-(Q25-BY25),2)) -> 175515.71 | AV25: =IF(R$8=0,0,ROUND(AV24-(R25-BZ25),2)) -> 0 | AW25: =IF(S$8=0,0,ROUND(AW24-(S25-CA25),2)) -> 0 | AX25: =IF(T$8=0,0,ROUND(AX24-(T25-CB25),2)) -> 0 | AY25: =IF(U$8=0,0,ROUND(AY24-(U25-CC25),2)) -> 0 | AZ25: =IF(V$8=0,0,ROUND(AZ24-(V25-CD25),2)) -> 0 | BA25: =IF(W$8=0,0,ROUND(BA24-(W25-CE25),2)) -> 0 | ... BK25: =IF(AG$8=0,0,ROUND(BK24-(AG25-CO25),2)) -> 0 | BL25: =SUM(AI25:BK25) -> 287695.09 | BN25: =ROUND(AI24*E$9/12,2) -> 0 | BO25: =ROUND(AJ24*F$9/12,2) -> 0 | BP25: =ROUND(AK24*G$9/12,2) -> 0 | BQ25: =ROUND(AL24*H$9/12,2) -> 0 | BR25: =ROUND(AM24*I$9/12,2) -> 0 | BS25: =ROUND(AN24*J$9/12,2) -> 13.09 | BT25: =ROUND(AO24*K$9/12,2) -> 65.02 | BU25: =ROUND(AP24*L$9/12,2) -> 84.9 | ... CP25: =ROUND(BK24*AG$9/12,2) -> 0 | CR25: =SUM(BN25:CP25) -> 1765.4 | CT25: =IF(AI24>0,IF((AI24+BN25)<E$10,AI24+BN25,E$10),0) -> 0 | CU25: =IF(AJ24>0,IF((AJ24+BO25)<F$10,AJ24+BO25,F$10),0) -> 0 | CV25: =IF(AK24>0,IF((AK24+BP25)<G$10,AK24+BP25,G$10),0) -> 0 | CW25: =IF(AL24>0,IF((AL24+BQ25)<H$10,AL24+BQ25,H$10),0) -> 0 | CX25: =IF(AM24>0,IF((AM24+BR25)<I$10,AM24+BR25,I$10),0) -> 20.96 | CY25: =IF(AN24>0,IF((AN24+BS25)<J$10,AN24+BS25,J$10),0) -> 35 | CZ25: =IF(AO24>0,IF((AO24+BT25)<K$10,AO24+BT25,K$10),0) -> 206 | DA25: =IF(AP24>0,IF((AP24+BU25)<L$10,AP24+BU25,L$10),0) -> 82 | ... DX25: =IF(BM24>0,IF((BM24+CR25)<AI$10,BM24+CR25,AI$10),0) -> 0 | DY25: =SUM(CT25:DX25) -> 3849.93 | EA25: =IF(AI23<=0,0,IF(CT24+$C24>AI23+BN24,AI23+BN24-CT24,$C24)) -> 0 | EB25: =IF(AJ23<=0,0,IF($C24<=SUM($EA25:EA25),0,IF(CU24+$C24-SUM($EA25:EA25)>AJ23+BO24,AJ23+BO24-CU24,$C24-SUM($EA25:EA25)))) -> 0 | EC25: =IF(AK23<=0,0,IF($C24<=SUM($EA25:EB25),0,IF(CV24+$C24-SUM($EA25:EB25)>AK23+BP24,AK23+BP24-CV24,$C24-SUM($EA25:EB25)))) -> 0 | ED25: =IF(AL23<=0,0,IF($C24<=SUM($EA25:EC25),0,IF(CW24+$C24-SUM($EA25:EC25)>AL23+BQ24,AL23+BQ24-CW24,$C24-SUM($EA25:EC25)))) -> 0 | EE25: =IF(AM23<=0,0,IF($C24<=SUM($EA25:ED25),0,IF(CX24+$C24-SUM($EA25:ED25)>AM23+BR24,AM23+BR24-CX24,$C24-SUM($EA25:ED25)))) -> 0 | EF25: =IF(AN23<=0,0,IF($C24<=SUM($EA25:EE25),0,IF(CY24+$C24-SUM($EA25:EE25)>AN23+BS24,AN23+BS24-CY24,$C24-SUM($EA25:EE25)))) -> 0 | EG25: =IF(AO23<=0,0,IF($C24<=SUM($EA25:EF25),0,IF(CZ24+$C24-SUM($EA25:EF25)>AO23+BT24,AO23+BT24-CZ24,$C24-SUM($EA25:EF25)))) -> 0 | EH25: =IF(AP23<=0,0,IF($C24<=SUM($EA25:EG25),0,IF(DA24+$C24-SUM($EA25:EG25)>AP23+BU24,AP23+BU24-DA24,$C24-SUM($EA25:EG25)))) -> 0 | EI25: =IF(AQ23<=0,0,IF($C24<=SUM($EA25:EH25),0,IF(DB24+$C24-SUM($EA25:EH25)>AQ23+BV24,AQ23+BV24-DB24,$C24-SUM($EA25:EH25)))) -> 0 | ... FC25: =IF(BK23<=0,0,IF($C24<=SUM($EA25:FB25),0,IF(DV24+$C24-SUM($EA25:FB25)>BK23+CP24,BK23+CP24-DV24,$C24-SUM($EA25:FB25)))) -> 0
A26: =IF(SUM(AI25:BK25)<=0,"",A25+1) -> 6 | B26: 45809 | C26: =IF(A26="","",IF(Calculator!snowball,IF(($E$5-DY26)<0,0,$E$5-DY26),0)+D26) -> 33.03 | E26: =CT26+EA27 -> 0 | F26: =CU26+EB27 -> 0 | G26: =CV26+EC27 -> 0 | H26: =CW26+ED27 -> 0 | I26: =CX26+EE27 -> 0 | J26: 35 | K26: 73 | L26: 80 | M26: 133 | N26: =DC26+EJ27 -> 450.08 | P26: =DE26+EL27 -> 791.16 | Q26: 1487.37 | R26: =DG26+EN27 -> 0 | S26: =DH26+EO27 -> 0 | T26: =DI26+EP27 -> 0 | U26: =DJ26+EQ27 -> 0 | V26: =DK26+ER27 -> 0 | W26: =DL26+ES27 -> 0 | X26: =DM26+ET27 -> 0 | Y26: =DN26+EU27 -> 0 | ... AG26: =DV26+FC27 -> 0 | AH26: =SUM(AI26:BK26) -> 286216.5 | AI26: =IF(E$8=0,0,ROUND(AI25-(E26-BN26),2)) -> 0 | AJ26: =IF(F$8=0,0,ROUND(AJ25-(F26-BO26),2)) -> 0 | AK26: =IF(G$8=0,0,ROUND(AK25-(G26-BP26),2)) -> 0 | AL26: =IF(H$8=0,0,ROUND(AL25-(H26-BQ26),2)) -> 0 | AM26: =IF(I$8=0,0,ROUND(AM25-(I26-BR26),2)) -> 0 | AN26: =IF(J$8=0,0,ROUND(AN25-(J26-BS26),2)) -> 482.75 | AO26: =IF(K$8=0,0,ROUND(AO25-(K26-BT26),2)) -> 2448.34 | AP26: =IF(L$8=0,0,ROUND(AP25-(L26-BU26),2)) -> 3216.84 | ... AS26: =IF(O$8=0,0,ROUND(AS25-(O26-BX26),2)) -> 40275.81 | AT26: =IF(P$8=0,0,ROUND(AT25-(P26-BX26),2)) -> 47398.85 | AU26: =IF(Q$8=0,0,ROUND(AU25-(Q26-BY26),2)) -> 174398.18 | AV26: =IF(R$8=0,0,ROUND(AV25-(R26-BZ26),2)) -> 0 | AW26: =IF(S$8=0,0,ROUND(AW25-(S26-CA26),2)) -> 0 | AX26: =IF(T$8=0,0,ROUND(AX25-(T26-CB26),2)) -> 0 | AY26: =IF(U$8=0,0,ROUND(AY25-(U26-CC26),2)) -> 0 | AZ26: =IF(V$8=0,0,ROUND(AZ25-(V26-CD26),2)) -> 0 | BA26: =IF(W$8=0,0,ROUND(BA25-(W26-CE26),2)) -> 0 | ... BK26: =IF(AG$8=0,0,ROUND(BK25-(AG26-CO26),2)) -> 0 | BL26: =SUM(AI26:BK26) -> 286216.5 | BN26: =ROUND(AI25*E$9/12,2) -> 0 | BO26: =ROUND(AJ25*F$9/12,2) -> 0 | BP26: =ROUND(AK25*G$9/12,2) -> 0 | BQ26: =ROUND(AL25*H$9/12,2) -> 0 | BR26: =ROUND(AM25*I$9/12,2) -> 0 | BS26: =ROUND(AN25*J$9/12,2) -> 12.55 | BT26: =ROUND(AO25*K$9/12,2) -> 61.5 | BU26: =ROUND(AP25*L$9/12,2) -> 84.95 | ... CP26: =ROUND(BK25*AG$9/12,2) -> 0 | CR26: =SUM(BN26:CP26) -> 1753.67 | CT26: =IF(AI25>0,IF((AI25+BN26)<E$10,AI25+BN26,E$10),0) -> 0 | CU26: =IF(AJ25>0,IF((AJ25+BO26)<F$10,AJ25+BO26,F$10),0) -> 0 | CV26: =IF(AK25>0,IF((AK25+BP26)<G$10,AK25+BP26,G$10),0) -> 0 | CW26: =IF(AL25>0,IF((AL25+BQ26)<H$10,AL25+BQ26,H$10),0) -> 0 | CX26: =IF(AM25>0,IF((AM25+BR26)<I$10,AM25+BR26,I$10),0) -> 0 | CY26: =IF(AN25>0,IF((AN25+BS26)<J$10,AN25+BS26,J$10),0) -> 35 | CZ26: =IF(AO25>0,IF((AO25+BT26)<K$10,AO25+BT26,K$10),0) -> 206 | DA26: =IF(AP25>0,IF((AP25+BU26)<L$10,AP25+BU26,L$10),0) -> 82 | ... DX26: =IF(BM25>0,IF((BM25+CR26)<AI$10,BM25+CR26,AI$10),0) -> 0 | DY26: =SUM(CT26:DX26) -> 3828.97 | EA26: =IF(AI24<=0,0,IF(CT25+$C25>AI24+BN25,AI24+BN25-CT25,$C25)) -> 0 | EB26: =IF(AJ24<=0,0,IF($C25<=SUM($EA26:EA26),0,IF(CU25+$C25-SUM($EA26:EA26)>AJ24+BO25,AJ24+BO25-CU25,$C25-SUM($EA26:EA26)))) -> 0 | EC26: =IF(AK24<=0,0,IF($C25<=SUM($EA26:EB26),0,IF(CV25+$C25-SUM($EA26:EB26)>AK24+BP25,AK24+BP25-CV25,$C25-SUM($EA26:EB26)))) -> 0 | ED26: =IF(AL24<=0,0,IF($C25<=SUM($EA26:EC26),0,IF(CW25+$C25-SUM($EA26:EC26)>AL24+BQ25,AL24+BQ25-CW25,$C25-SUM($EA26:EC26)))) -> 0 | EE26: =IF(AM24<=0,0,IF($C25<=SUM($EA26:ED26),0,IF(CX25+$C25-SUM($EA26:ED26)>AM24+BR25,AM24+BR25-CX25,$C25-SUM($EA26:ED26)))) -> 12.07 | EF26: =IF(AN24<=0,0,IF($C25<=SUM($EA26:EE26),0,IF(CY25+$C25-SUM($EA26:EE26)>AN24+BS25,AN24+BS25-CY25,$C25-SUM($EA26:EE26)))) -> 0 | EG26: =IF(AO24<=0,0,IF($C25<=SUM($EA26:EF26),0,IF(CZ25+$C25-SUM($EA26:EF26)>AO24+BT25,AO24+BT25-CZ25,$C25-SUM($EA26:EF26)))) -> 0 | EH26: =IF(AP24<=0,0,IF($C25<=SUM($EA26:EG26),0,IF(DA25+$C25-SUM($EA26:EG26)>AP24+BU25,AP24+BU25-DA25,$C25-SUM($EA26:EG26)))) -> 0 | EI26: =IF(AQ24<=0,0,IF($C25<=SUM($EA26:EH26),0,IF(DB25+$C25-SUM($EA26:EH26)>AQ24+BV25,AQ24+BV25-DB25,$C25-SUM($EA26:EH26)))) -> 0 | ... FC26: =IF(BK24<=0,0,IF($C25<=SUM($EA26:FB26),0,IF(DV25+$C25-SUM($EA26:FB26)>BK24+CP25,BK24+CP25-DV25,$C25-SUM($EA26:FB26)))) -> 0
A27: =IF(SUM(AI26:BK26)<=0,"",A26+1) -> 7 | B27: 45839 | C27: =IF(A27="","",IF(Calculator!snowball,IF(($E$5-DY27)<0,0,$E$5-DY27),0)+D27) -> 33.03 | E27: =CT27+EA28 -> 0 | F27: =CU27+EB28 -> 0 | G27: =CV27+EC28 -> 0 | H27: =CW27+ED28 -> 0 | I27: =CX27+EE28 -> 0 | J27: 35 | K27: 100 | L27: 77 | M27: 129 | N27: =DC27+EJ28 -> 450.08 | P27: =DE27+EL28 -> 791.16 | Q27: 1487.37 | R27: =DG27+EN28 -> 0 | S27: =DH27+EO28 -> 0 | T27: =DI27+EP28 -> 0 | U27: =DJ27+EQ28 -> 0 | V27: =DK27+ER28 -> 0 | W27: =DL27+ES28 -> 0 | X27: =DM27+ET28 -> 0 | Y27: =DN27+EU28 -> 0 | ... AG27: =DV27+FC28 -> 0 | AH27: =SUM(AI27:BK27) -> 284716.12 | AI27: =IF(E$8=0,0,ROUND(AI26-(E27-BN27),2)) -> 0 | AJ27: =IF(F$8=0,0,ROUND(AJ26-(F27-BO27),2)) -> 0 | AK27: =IF(G$8=0,0,ROUND(AK26-(G27-BP27),2)) -> 0 | AL27: =IF(H$8=0,0,ROUND(AL26-(H27-BQ27),2)) -> 0 | AM27: =IF(I$8=0,0,ROUND(AM26-(I27-BR27),2)) -> 0 | AN27: =IF(J$8=0,0,ROUND(AN26-(J27-BS27),2)) -> 459.74 | AO27: =IF(K$8=0,0,ROUND(AO26-(K27-BT27),2)) -> 2409.55 | AP27: =IF(L$8=0,0,ROUND(AP26-(L27-BU27),2)) -> 3224.93 | ... AS27: =IF(O$8=0,0,ROUND(AS26-(O27-BX27),2)) -> 40645 | AT27: =IF(P$8=0,0,ROUND(AT26-(P27-BX27),2)) -> 46976.88 | AU27: =IF(Q$8=0,0,ROUND(AU26-(Q27-BY27),2)) -> 173277.36 | AV27: =IF(R$8=0,0,ROUND(AV26-(R27-BZ27),2)) -> 0 | AW27: =IF(S$8=0,0,ROUND(AW26-(S27-CA27),2)) -> 0 | AX27: =IF(T$8=0,0,ROUND(AX26-(T27-CB27),2)) -> 0 | AY27: =IF(U$8=0,0,ROUND(AY26-(U27-CC27),2)) -> 0 | AZ27: =IF(V$8=0,0,ROUND(AZ26-(V27-CD27),2)) -> 0 | BA27: =IF(W$8=0,0,ROUND(BA26-(W27-CE27),2)) -> 0 | ... BK27: =IF(AG$8=0,0,ROUND(BK26-(AG27-CO27),2)) -> 0 | BL27: =SUM(AI27:BK27) -> 284716.12 | BN27: =ROUND(AI26*E$9/12,2) -> 0 | BO27: =ROUND(AJ26*F$9/12,2) -> 0 | BP27: =ROUND(AK26*G$9/12,2) -> 0 | BQ27: =ROUND(AL26*H$9/12,2) -> 0 | BR27: =ROUND(AM26*I$9/12,2) -> 0 | BS27: =ROUND(AN26*J$9/12,2) -> 11.99 | BT27: =ROUND(AO26*K$9/12,2) -> 61.21 | BU27: =ROUND(AP26*L$9/12,2) -> 85.09 | ... CP27: =ROUND(BK26*AG$9/12,2) -> 0 | CR27: =SUM(BN27:CP27) -> 1745.03 | CT27: =IF(AI26>0,IF((AI26+BN27)<E$10,AI26+BN27,E$10),0) -> 0 | CU27: =IF(AJ26>0,IF((AJ26+BO27)<F$10,AJ26+BO27,F$10),0) -> 0 | CV27: =IF(AK26>0,IF((AK26+BP27)<G$10,AK26+BP27,G$10),0) -> 0 | CW27: =IF(AL26>0,IF((AL26+BQ27)<H$10,AL26+BQ27,H$10),0) -> 0 | CX27: =IF(AM26>0,IF((AM26+BR27)<I$10,AM26+BR27,I$10),0) -> 0 | CY27: =IF(AN26>0,IF((AN26+BS27)<J$10,AN26+BS27,J$10),0) -> 35 | CZ27: =IF(AO26>0,IF((AO26+BT27)<K$10,AO26+BT27,K$10),0) -> 206 | DA27: =IF(AP26>0,IF((AP26+BU27)<L$10,AP26+BU27,L$10),0) -> 82 | ... DX27: =IF(BM26>0,IF((BM26+CR27)<AI$10,BM26+CR27,AI$10),0) -> 0 | DY27: =SUM(CT27:DX27) -> 3828.97 | EA27: =IF(AI25<=0,0,IF(CT26+$C26>AI25+BN26,AI25+BN26-CT26,$C26)) -> 0 | EB27: =IF(AJ25<=0,0,IF($C26<=SUM($EA27:EA27),0,IF(CU26+$C26-SUM($EA27:EA27)>AJ25+BO26,AJ25+BO26-CU26,$C26-SUM($EA27:EA27)))) -> 0 | EC27: =IF(AK25<=0,0,IF($C26<=SUM($EA27:EB27),0,IF(CV26+$C26-SUM($EA27:EB27)>AK25+BP26,AK25+BP26-CV26,$C26-SUM($EA27:EB27)))) -> 0 | ED27: =IF(AL25<=0,0,IF($C26<=SUM($EA27:EC27),0,IF(CW26+$C26-SUM($EA27:EC27)>AL25+BQ26,AL25+BQ26-CW26,$C26-SUM($EA27:EC27)))) -> 0 | EE27: =IF(AM25<=0,0,IF($C26<=SUM($EA27:ED27),0,IF(CX26+$C26-SUM($EA27:ED27)>AM25+BR26,AM25+BR26-CX26,$C26-SUM($EA27:ED27)))) -> 0 | EF27: =IF(AN25<=0,0,IF($C26<=SUM($EA27:EE27),0,IF(CY26+$C26-SUM($EA27:EE27)>AN25+BS26,AN25+BS26-CY26,$C26-SUM($EA27:EE27)))) -> 33.03 | EG27: =IF(AO25<=0,0,IF($C26<=SUM($EA27:EF27),0,IF(CZ26+$C26-SUM($EA27:EF27)>AO25+BT26,AO25+BT26-CZ26,$C26-SUM($EA27:EF27)))) -> 0 | EH27: =IF(AP25<=0,0,IF($C26<=SUM($EA27:EG27),0,IF(DA26+$C26-SUM($EA27:EG27)>AP25+BU26,AP25+BU26-DA26,$C26-SUM($EA27:EG27)))) -> 0 | EI27: =IF(AQ25<=0,0,IF($C26<=SUM($EA27:EH27),0,IF(DB26+$C26-SUM($EA27:EH27)>AQ25+BV26,AQ25+BV26-DB26,$C26-SUM($EA27:EH27)))) -> 0 | ... FC27: =IF(BK25<=0,0,IF($C26<=SUM($EA27:FB27),0,IF(DV26+$C26-SUM($EA27:FB27)>BK25+CP26,BK25+CP26-DV26,$C26-SUM($EA27:FB27)))) -> 0
A28: =IF(SUM(AI27:BK27)<=0,"",A27+1) -> 8 | B28: 45870 | C28: =IF(A28="","",IF(Calculator!snowball,IF(($E$5-DY28)<0,0,$E$5-DY28),0)+D28) -> 33.03 | E28: =CT28+EA29 -> 0 | F28: =CU28+EB29 -> 0 | G28: =CV28+EC29 -> 0 | H28: =CW28+ED29 -> 0 | I28: =CX28+EE29 -> 0 | J28: 35 | K28: 98 | L28: 80 | M28: 131 | N28: =DC28+EJ29 -> 450.08 | P28: =DE28+EL29 -> 791.16 | Q28: 1487.37 | R28: =DG28+EN29 -> 0 | S28: =DH28+EO29 -> 0 | T28: =DI28+EP29 -> 0 | U28: =DJ28+EQ29 -> 0 | V28: =DK28+ER29 -> 0 | W28: =DL28+ES29 -> 0 | X28: =DM28+ET29 -> 0 | Y28: =DN28+EU29 -> 0 | ... AG28: =DV28+FC29 -> 0 | AH28: =SUM(AI28:BK28) -> 283210.47 | AI28: =IF(E$8=0,0,ROUND(AI27-(E28-BN28),2)) -> 0 | AJ28: =IF(F$8=0,0,ROUND(AJ27-(F28-BO28),2)) -> 0 | AK28: =IF(G$8=0,0,ROUND(AK27-(G28-BP28),2)) -> 0 | AL28: =IF(H$8=0,0,ROUND(AL27-(H28-BQ28),2)) -> 0 | AM28: =IF(I$8=0,0,ROUND(AM27-(I28-BR28),2)) -> 0 | AN28: =IF(J$8=0,0,ROUND(AN27-(J28-BS28),2)) -> 436.16 | AO28: =IF(K$8=0,0,ROUND(AO27-(K28-BT28),2)) -> 2371.79 | AP28: =IF(L$8=0,0,ROUND(AP27-(L28-BU28),2)) -> 3230.23 | ... AS28: =IF(O$8=0,0,ROUND(AS27-(O28-BX28),2)) -> 41017.58 | AT28: =IF(P$8=0,0,ROUND(AT27-(P28-BX28),2)) -> 46558.3 | AU28: =IF(Q$8=0,0,ROUND(AU27-(Q28-BY28),2)) -> 172153.28 | AV28: =IF(R$8=0,0,ROUND(AV27-(R28-BZ28),2)) -> 0 | AW28: =IF(S$8=0,0,ROUND(AW27-(S28-CA28),2)) -> 0 | AX28: =IF(T$8=0,0,ROUND(AX27-(T28-CB28),2)) -> 0 | AY28: =IF(U$8=0,0,ROUND(AY27-(U28-CC28),2)) -> 0 | AZ28: =IF(V$8=0,0,ROUND(AZ27-(V28-CD28),2)) -> 0 | BA28: =IF(W$8=0,0,ROUND(BA27-(W28-CE28),2)) -> 0 | ... BK28: =IF(AG$8=0,0,ROUND(BK27-(AG28-CO28),2)) -> 0 | BL28: =SUM(AI28:BK28) -> 283210.47 | BN28: =ROUND(AI27*E$9/12,2) -> 0 | BO28: =ROUND(AJ27*F$9/12,2) -> 0 | BP28: =ROUND(AK27*G$9/12,2) -> 0 | BQ28: =ROUND(AL27*H$9/12,2) -> 0 | BR28: =ROUND(AM27*I$9/12,2) -> 0 | BS28: =ROUND(AN27*J$9/12,2) -> 11.42 | BT28: =ROUND(AO27*K$9/12,2) -> 60.24 | BU28: =ROUND(AP27*L$9/12,2) -> 85.3 | ... CP28: =ROUND(BK27*AG$9/12,2) -> 0 | CR28: =SUM(BN28:CP28) -> 1735.87 | CT28: =IF(AI27>0,IF((AI27+BN28)<E$10,AI27+BN28,E$10),0) -> 0 | CU28: =IF(AJ27>0,IF((AJ27+BO28)<F$10,AJ27+BO28,F$10),0) -> 0 | CV28: =IF(AK27>0,IF((AK27+BP28)<G$10,AK27+BP28,G$10),0) -> 0 | CW28: =IF(AL27>0,IF((AL27+BQ28)<H$10,AL27+BQ28,H$10),0) -> 0 | CX28: =IF(AM27>0,IF((AM27+BR28)<I$10,AM27+BR28,I$10),0) -> 0 | CY28: =IF(AN27>0,IF((AN27+BS28)<J$10,AN27+BS28,J$10),0) -> 35 | CZ28: =IF(AO27>0,IF((AO27+BT28)<K$10,AO27+BT28,K$10),0) -> 206 | DA28: =IF(AP27>0,IF((AP27+BU28)<L$10,AP27+BU28,L$10),0) -> 82 | ... DX28: =IF(BM27>0,IF((BM27+CR28)<AI$10,BM27+CR28,AI$10),0) -> 0 | DY28: =SUM(CT28:DX28) -> 3828.97 | EA28: =IF(AI26<=0,0,IF(CT27+$C27>AI26+BN27,AI26+BN27-CT27,$C27)) -> 0 | EB28: =IF(AJ26<=0,0,IF($C27<=SUM($EA28:EA28),0,IF(CU27+$C27-SUM($EA28:EA28)>AJ26+BO27,AJ26+BO27-CU27,$C27-SUM($EA28:EA28)))) -> 0 | EC28: =IF(AK26<=0,0,IF($C27<=SUM($EA28:EB28),0,IF(CV27+$C27-SUM($EA28:EB28)>AK26+BP27,AK26+BP27-CV27,$C27-SUM($EA28:EB28)))) -> 0 | ED28: =IF(AL26<=0,0,IF($C27<=SUM($EA28:EC28),0,IF(CW27+$C27-SUM($EA28:EC28)>AL26+BQ27,AL26+BQ27-CW27,$C27-SUM($EA28:EC28)))) -> 0 | EE28: =IF(AM26<=0,0,IF($C27<=SUM($EA28:ED28),0,IF(CX27+$C27-SUM($EA28:ED28)>AM26+BR27,AM26+BR27-CX27,$C27-SUM($EA28:ED28)))) -> 0 | EF28: =IF(AN26<=0,0,IF($C27<=SUM($EA28:EE28),0,IF(CY27+$C27-SUM($EA28:EE28)>AN26+BS27,AN26+BS27-CY27,$C27-SUM($EA28:EE28)))) -> 33.03 | EG28: =IF(AO26<=0,0,IF($C27<=SUM($EA28:EF28),0,IF(CZ27+$C27-SUM($EA28:EF28)>AO26+BT27,AO26+BT27-CZ27,$C27-SUM($EA28:EF28)))) -> 0 | EH28: =IF(AP26<=0,0,IF($C27<=SUM($EA28:EG28),0,IF(DA27+$C27-SUM($EA28:EG28)>AP26+BU27,AP26+BU27-DA27,$C27-SUM($EA28:EG28)))) -> 0 | EI28: =IF(AQ26<=0,0,IF($C27<=SUM($EA28:EH28),0,IF(DB27+$C27-SUM($EA28:EH28)>AQ26+BV27,AQ26+BV27-DB27,$C27-SUM($EA28:EH28)))) -> 0 | ... FC28: =IF(BK26<=0,0,IF($C27<=SUM($EA28:FB28),0,IF(DV27+$C27-SUM($EA28:FB28)>BK26+CP27,BK26+CP27-DV27,$C27-SUM($EA28:FB28)))) -> 0
